2023-08-21 08:51:01,128 - INFO - __main__ : 46 - Logging enabled
2023-08-21 08:51:01,180 - INFO - __main__ : 432 - *** Running server in insecure mode on port: 50052 ***
2023-08-21 08:51:13,204 - INFO - __main__ : 323 - GetCapabilities
2023-08-21 08:51:13,234 - INFO - __main__ : 348 - Adding to capabilities: SumOfRows(['col1', 'col2'])
2023-08-21 08:51:13,234 - INFO - __main__ : 348 - Adding to capabilities: SumOfColumn(['col1'])
2023-08-21 08:51:13,237 - INFO - __main__ : 348 - Adding to capabilities: MaxOfColumns_2(['col1', 'col2'])
2023-08-21 08:51:13,239 - INFO - __main__ : 348 - Adding to capabilities: RandomForest(['col1'])
2023-08-21 08:51:14,471 - INFO - __main__ : 365 - ExecuteFunction (functionId: 3)
2023-08-21 08:51:18,368 - INFO - __main__ : 323 - GetCapabilities
2023-08-21 08:51:18,369 - INFO - __main__ : 348 - Adding to capabilities: SumOfRows(['col1', 'col2'])
2023-08-21 08:51:18,369 - INFO - __main__ : 348 - Adding to capabilities: SumOfColumn(['col1'])
2023-08-21 08:51:18,370 - INFO - __main__ : 348 - Adding to capabilities: MaxOfColumns_2(['col1', 'col2'])
2023-08-21 08:51:18,370 - INFO - __main__ : 348 - Adding to capabilities: RandomForest(['col1'])
2023-08-21 08:57:07,300 - INFO - __main__ : 46 - Logging enabled
2023-08-21 08:57:07,311 - INFO - __main__ : 431 - *** Running server in insecure mode on port: 50052 ***
2023-08-21 08:57:07,780 - INFO - __main__ : 364 - ExecuteFunction (functionId: 3)
2023-08-21 08:58:36,181 - INFO - __main__ : 46 - Logging enabled
2023-08-21 08:58:36,187 - INFO - __main__ : 432 - *** Running server in insecure mode on port: 50052 ***
2023-08-21 08:58:36,211 - INFO - __main__ : 365 - ExecuteFunction (functionId: 3)
2023-08-21 08:59:01,566 - INFO - __main__ : 46 - Logging enabled
2023-08-21 08:59:01,572 - INFO - __main__ : 432 - *** Running server in insecure mode on port: 50052 ***
2023-08-21 08:59:01,674 - INFO - __main__ : 365 - ExecuteFunction (functionId: 3)
2023-08-21 08:59:19,441 - INFO - __main__ : 46 - Logging enabled
2023-08-21 08:59:19,453 - INFO - __main__ : 432 - *** Running server in insecure mode on port: 50052 ***
2023-08-21 08:59:19,544 - INFO - __main__ : 365 - ExecuteFunction (functionId: 3)
2023-08-21 09:11:57,216 - INFO - __main__ : 46 - Logging enabled
2023-08-21 09:11:57,224 - INFO - __main__ : 446 - *** Running server in insecure mode on port: 50052 ***
2023-08-21 09:11:57,534 - INFO - __main__ : 379 - ExecuteFunction (functionId: 3)
2023-08-21 09:11:57,670 - ERROR - _server : 471 - Exception iterating responses: cannot unpack non-iterable int object
Traceback (most recent call last):
  File "C:\Users\analytiikka\miniconda3\envs\mlModels\lib\site-packages\grpc\_server.py", line 461, in _take_response_from_response_iterator
    return next(response_iterator), True
  File "__main__.py", line 188, in _random_forest
    final_loss, iterations  = 0
TypeError: cannot unpack non-iterable int object
2023-08-21 09:11:57,678 - INFO - __main__ : 379 - ExecuteFunction (functionId: 3)
2023-08-21 09:11:57,742 - ERROR - _server : 471 - Exception iterating responses: cannot unpack non-iterable int object
Traceback (most recent call last):
  File "C:\Users\analytiikka\miniconda3\envs\mlModels\lib\site-packages\grpc\_server.py", line 461, in _take_response_from_response_iterator
    return next(response_iterator), True
  File "__main__.py", line 188, in _random_forest
    final_loss, iterations  = 0
TypeError: cannot unpack non-iterable int object
2023-08-21 09:11:57,748 - INFO - __main__ : 379 - ExecuteFunction (functionId: 3)
2023-08-21 09:11:57,810 - ERROR - _server : 471 - Exception iterating responses: cannot unpack non-iterable int object
Traceback (most recent call last):
  File "C:\Users\analytiikka\miniconda3\envs\mlModels\lib\site-packages\grpc\_server.py", line 461, in _take_response_from_response_iterator
    return next(response_iterator), True
  File "__main__.py", line 188, in _random_forest
    final_loss, iterations  = 0
TypeError: cannot unpack non-iterable int object
2023-08-21 09:11:57,812 - INFO - __main__ : 379 - ExecuteFunction (functionId: 3)
2023-08-21 09:11:57,922 - ERROR - _server : 471 - Exception iterating responses: cannot unpack non-iterable int object
Traceback (most recent call last):
  File "C:\Users\analytiikka\miniconda3\envs\mlModels\lib\site-packages\grpc\_server.py", line 461, in _take_response_from_response_iterator
    return next(response_iterator), True
  File "__main__.py", line 188, in _random_forest
    final_loss, iterations  = 0
TypeError: cannot unpack non-iterable int object
2023-08-21 09:12:20,282 - INFO - __main__ : 46 - Logging enabled
2023-08-21 09:12:20,288 - INFO - __main__ : 447 - *** Running server in insecure mode on port: 50052 ***
2023-08-21 09:12:20,720 - INFO - __main__ : 380 - ExecuteFunction (functionId: 3)
2023-08-21 09:12:20,860 - ERROR - _server : 471 - Exception iterating responses: too many values to unpack (expected 2)
Traceback (most recent call last):
  File "C:\Users\analytiikka\miniconda3\envs\mlModels\lib\site-packages\grpc\_server.py", line 461, in _take_response_from_response_iterator
    return next(response_iterator), True
  File "__main__.py", line 192, in _random_forest
    xb,yb = learn.dls.one_batch()
ValueError: too many values to unpack (expected 2)
2023-08-21 09:12:20,862 - INFO - __main__ : 380 - ExecuteFunction (functionId: 3)
2023-08-21 09:12:20,912 - ERROR - _server : 471 - Exception iterating responses: too many values to unpack (expected 2)
Traceback (most recent call last):
  File "C:\Users\analytiikka\miniconda3\envs\mlModels\lib\site-packages\grpc\_server.py", line 461, in _take_response_from_response_iterator
    return next(response_iterator), True
  File "__main__.py", line 192, in _random_forest
    xb,yb = learn.dls.one_batch()
ValueError: too many values to unpack (expected 2)
2023-08-21 09:12:20,918 - INFO - __main__ : 380 - ExecuteFunction (functionId: 3)
2023-08-21 09:12:21,061 - ERROR - _server : 471 - Exception iterating responses: too many values to unpack (expected 2)
Traceback (most recent call last):
  File "C:\Users\analytiikka\miniconda3\envs\mlModels\lib\site-packages\grpc\_server.py", line 461, in _take_response_from_response_iterator
    return next(response_iterator), True
  File "__main__.py", line 192, in _random_forest
    xb,yb = learn.dls.one_batch()
ValueError: too many values to unpack (expected 2)
2023-08-21 09:12:21,062 - INFO - __main__ : 380 - ExecuteFunction (functionId: 3)
2023-08-21 09:12:21,131 - ERROR - _server : 471 - Exception iterating responses: too many values to unpack (expected 2)
Traceback (most recent call last):
  File "C:\Users\analytiikka\miniconda3\envs\mlModels\lib\site-packages\grpc\_server.py", line 461, in _take_response_from_response_iterator
    return next(response_iterator), True
  File "__main__.py", line 192, in _random_forest
    xb,yb = learn.dls.one_batch()
ValueError: too many values to unpack (expected 2)
2023-08-21 09:18:03,654 - INFO - __main__ : 46 - Logging enabled
2023-08-21 09:18:03,661 - INFO - __main__ : 449 - *** Running server in insecure mode on port: 50052 ***
2023-08-21 09:18:04,091 - INFO - __main__ : 382 - ExecuteFunction (functionId: 3)
2023-08-21 09:18:04,226 - ERROR - _server : 471 - Exception iterating responses: too many values to unpack (expected 2)
Traceback (most recent call last):
  File "C:\Users\analytiikka\miniconda3\envs\mlModels\lib\site-packages\grpc\_server.py", line 461, in _take_response_from_response_iterator
    return next(response_iterator), True
  File "__main__.py", line 194, in _random_forest
    xb,yb = learn.dls.one_batch()
ValueError: too many values to unpack (expected 2)
2023-08-21 09:18:04,230 - INFO - __main__ : 382 - ExecuteFunction (functionId: 3)
2023-08-21 09:18:04,341 - ERROR - _server : 471 - Exception iterating responses: too many values to unpack (expected 2)
Traceback (most recent call last):
  File "C:\Users\analytiikka\miniconda3\envs\mlModels\lib\site-packages\grpc\_server.py", line 461, in _take_response_from_response_iterator
    return next(response_iterator), True
  File "__main__.py", line 194, in _random_forest
    xb,yb = learn.dls.one_batch()
ValueError: too many values to unpack (expected 2)
2023-08-21 09:18:04,343 - INFO - __main__ : 382 - ExecuteFunction (functionId: 3)
2023-08-21 09:18:04,456 - ERROR - _server : 471 - Exception iterating responses: too many values to unpack (expected 2)
Traceback (most recent call last):
  File "C:\Users\analytiikka\miniconda3\envs\mlModels\lib\site-packages\grpc\_server.py", line 461, in _take_response_from_response_iterator
    return next(response_iterator), True
  File "__main__.py", line 194, in _random_forest
    xb,yb = learn.dls.one_batch()
ValueError: too many values to unpack (expected 2)
2023-08-21 09:18:04,459 - INFO - __main__ : 382 - ExecuteFunction (functionId: 3)
2023-08-21 09:18:04,529 - ERROR - _server : 471 - Exception iterating responses: too many values to unpack (expected 2)
Traceback (most recent call last):
  File "C:\Users\analytiikka\miniconda3\envs\mlModels\lib\site-packages\grpc\_server.py", line 461, in _take_response_from_response_iterator
    return next(response_iterator), True
  File "__main__.py", line 194, in _random_forest
    xb,yb = learn.dls.one_batch()
ValueError: too many values to unpack (expected 2)
2023-08-21 09:18:32,219 - INFO - __main__ : 46 - Logging enabled
2023-08-21 09:18:32,228 - INFO - __main__ : 449 - *** Running server in insecure mode on port: 50052 ***
2023-08-21 09:18:32,664 - INFO - __main__ : 382 - ExecuteFunction (functionId: 3)
2023-08-21 09:18:32,853 - ERROR - _server : 471 - Exception iterating responses: too many values to unpack (expected 2)
Traceback (most recent call last):
  File "C:\Users\analytiikka\miniconda3\envs\mlModels\lib\site-packages\grpc\_server.py", line 461, in _take_response_from_response_iterator
    return next(response_iterator), True
  File "__main__.py", line 194, in _random_forest
    xb,yb = learn.dls.one_batch()
ValueError: too many values to unpack (expected 2)
2023-08-21 09:18:32,856 - INFO - __main__ : 382 - ExecuteFunction (functionId: 3)
2023-08-21 09:18:33,010 - ERROR - _server : 471 - Exception iterating responses: too many values to unpack (expected 2)
Traceback (most recent call last):
  File "C:\Users\analytiikka\miniconda3\envs\mlModels\lib\site-packages\grpc\_server.py", line 461, in _take_response_from_response_iterator
    return next(response_iterator), True
  File "__main__.py", line 194, in _random_forest
    xb,yb = learn.dls.one_batch()
ValueError: too many values to unpack (expected 2)
2023-08-21 09:18:33,020 - INFO - __main__ : 382 - ExecuteFunction (functionId: 3)
2023-08-21 09:18:33,190 - ERROR - _server : 471 - Exception iterating responses: too many values to unpack (expected 2)
Traceback (most recent call last):
  File "C:\Users\analytiikka\miniconda3\envs\mlModels\lib\site-packages\grpc\_server.py", line 461, in _take_response_from_response_iterator
    return next(response_iterator), True
  File "__main__.py", line 194, in _random_forest
    xb,yb = learn.dls.one_batch()
ValueError: too many values to unpack (expected 2)
2023-08-21 09:18:33,191 - INFO - __main__ : 382 - ExecuteFunction (functionId: 3)
2023-08-21 09:18:33,344 - ERROR - _server : 471 - Exception iterating responses: too many values to unpack (expected 2)
Traceback (most recent call last):
  File "C:\Users\analytiikka\miniconda3\envs\mlModels\lib\site-packages\grpc\_server.py", line 461, in _take_response_from_response_iterator
    return next(response_iterator), True
  File "__main__.py", line 194, in _random_forest
    xb,yb = learn.dls.one_batch()
ValueError: too many values to unpack (expected 2)
2023-08-21 09:23:06,452 - INFO - __main__ : 46 - Logging enabled
2023-08-21 09:23:06,464 - INFO - __main__ : 450 - *** Running server in insecure mode on port: 50052 ***
2023-08-21 09:23:06,954 - INFO - __main__ : 383 - ExecuteFunction (functionId: 3)
2023-08-21 09:23:08,001 - ERROR - _server : 471 - Exception iterating responses: Expected tensor for argument #1 'indices' to have one of the following scalar types: Long, Int; but got torch.FloatTensor instead (while checking arguments for embedding)
Traceback (most recent call last):
  File "C:\Users\analytiikka\miniconda3\envs\mlModels\lib\site-packages\grpc\_server.py", line 461, in _take_response_from_response_iterator
    return next(response_iterator), True
  File "__main__.py", line 196, in _random_forest
    init_loss = learn.loss_func(learn.model(xb), yb)
  File "C:\Users\analytiikka\miniconda3\envs\mlModels\lib\site-packages\torch\nn\modules\module.py", line 1501, in _call_impl
    return forward_call(*args, **kwargs)
  File "C:\Users\analytiikka\miniconda3\envs\mlModels\lib\site-packages\fastai\tabular\model.py", line 67, in forward
    x = [e(x_cat[:,i]) for i,e in enumerate(self.embeds)]
  File "C:\Users\analytiikka\miniconda3\envs\mlModels\lib\site-packages\fastai\tabular\model.py", line 67, in <listcomp>
    x = [e(x_cat[:,i]) for i,e in enumerate(self.embeds)]
  File "C:\Users\analytiikka\miniconda3\envs\mlModels\lib\site-packages\torch\nn\modules\module.py", line 1501, in _call_impl
    return forward_call(*args, **kwargs)
  File "C:\Users\analytiikka\miniconda3\envs\mlModels\lib\site-packages\torch\nn\modules\sparse.py", line 162, in forward
    return F.embedding(
  File "C:\Users\analytiikka\miniconda3\envs\mlModels\lib\site-packages\torch\nn\functional.py", line 2210, in embedding
    return torch.embedding(weight, input, padding_idx, scale_grad_by_freq, sparse)
RuntimeError: Expected tensor for argument #1 'indices' to have one of the following scalar types: Long, Int; but got torch.FloatTensor instead (while checking arguments for embedding)
2023-08-21 09:23:08,009 - INFO - __main__ : 383 - ExecuteFunction (functionId: 3)
2023-08-21 09:23:08,099 - ERROR - _server : 471 - Exception iterating responses: Expected tensor for argument #1 'indices' to have one of the following scalar types: Long, Int; but got torch.FloatTensor instead (while checking arguments for embedding)
Traceback (most recent call last):
  File "C:\Users\analytiikka\miniconda3\envs\mlModels\lib\site-packages\grpc\_server.py", line 461, in _take_response_from_response_iterator
    return next(response_iterator), True
  File "__main__.py", line 196, in _random_forest
    init_loss = learn.loss_func(learn.model(xb), yb)
  File "C:\Users\analytiikka\miniconda3\envs\mlModels\lib\site-packages\torch\nn\modules\module.py", line 1501, in _call_impl
    return forward_call(*args, **kwargs)
  File "C:\Users\analytiikka\miniconda3\envs\mlModels\lib\site-packages\fastai\tabular\model.py", line 67, in forward
    x = [e(x_cat[:,i]) for i,e in enumerate(self.embeds)]
  File "C:\Users\analytiikka\miniconda3\envs\mlModels\lib\site-packages\fastai\tabular\model.py", line 67, in <listcomp>
    x = [e(x_cat[:,i]) for i,e in enumerate(self.embeds)]
  File "C:\Users\analytiikka\miniconda3\envs\mlModels\lib\site-packages\torch\nn\modules\module.py", line 1501, in _call_impl
    return forward_call(*args, **kwargs)
  File "C:\Users\analytiikka\miniconda3\envs\mlModels\lib\site-packages\torch\nn\modules\sparse.py", line 162, in forward
    return F.embedding(
  File "C:\Users\analytiikka\miniconda3\envs\mlModels\lib\site-packages\torch\nn\functional.py", line 2210, in embedding
    return torch.embedding(weight, input, padding_idx, scale_grad_by_freq, sparse)
RuntimeError: Expected tensor for argument #1 'indices' to have one of the following scalar types: Long, Int; but got torch.FloatTensor instead (while checking arguments for embedding)
2023-08-21 09:23:08,103 - INFO - __main__ : 383 - ExecuteFunction (functionId: 3)
2023-08-21 09:23:08,197 - ERROR - _server : 471 - Exception iterating responses: Expected tensor for argument #1 'indices' to have one of the following scalar types: Long, Int; but got torch.FloatTensor instead (while checking arguments for embedding)
Traceback (most recent call last):
  File "C:\Users\analytiikka\miniconda3\envs\mlModels\lib\site-packages\grpc\_server.py", line 461, in _take_response_from_response_iterator
    return next(response_iterator), True
  File "__main__.py", line 196, in _random_forest
    init_loss = learn.loss_func(learn.model(xb), yb)
  File "C:\Users\analytiikka\miniconda3\envs\mlModels\lib\site-packages\torch\nn\modules\module.py", line 1501, in _call_impl
    return forward_call(*args, **kwargs)
  File "C:\Users\analytiikka\miniconda3\envs\mlModels\lib\site-packages\fastai\tabular\model.py", line 67, in forward
    x = [e(x_cat[:,i]) for i,e in enumerate(self.embeds)]
  File "C:\Users\analytiikka\miniconda3\envs\mlModels\lib\site-packages\fastai\tabular\model.py", line 67, in <listcomp>
    x = [e(x_cat[:,i]) for i,e in enumerate(self.embeds)]
  File "C:\Users\analytiikka\miniconda3\envs\mlModels\lib\site-packages\torch\nn\modules\module.py", line 1501, in _call_impl
    return forward_call(*args, **kwargs)
  File "C:\Users\analytiikka\miniconda3\envs\mlModels\lib\site-packages\torch\nn\modules\sparse.py", line 162, in forward
    return F.embedding(
  File "C:\Users\analytiikka\miniconda3\envs\mlModels\lib\site-packages\torch\nn\functional.py", line 2210, in embedding
    return torch.embedding(weight, input, padding_idx, scale_grad_by_freq, sparse)
RuntimeError: Expected tensor for argument #1 'indices' to have one of the following scalar types: Long, Int; but got torch.FloatTensor instead (while checking arguments for embedding)
2023-08-21 09:23:08,201 - INFO - __main__ : 383 - ExecuteFunction (functionId: 3)
2023-08-21 09:23:08,302 - ERROR - _server : 471 - Exception iterating responses: Expected tensor for argument #1 'indices' to have one of the following scalar types: Long, Int; but got torch.FloatTensor instead (while checking arguments for embedding)
Traceback (most recent call last):
  File "C:\Users\analytiikka\miniconda3\envs\mlModels\lib\site-packages\grpc\_server.py", line 461, in _take_response_from_response_iterator
    return next(response_iterator), True
  File "__main__.py", line 196, in _random_forest
    init_loss = learn.loss_func(learn.model(xb), yb)
  File "C:\Users\analytiikka\miniconda3\envs\mlModels\lib\site-packages\torch\nn\modules\module.py", line 1501, in _call_impl
    return forward_call(*args, **kwargs)
  File "C:\Users\analytiikka\miniconda3\envs\mlModels\lib\site-packages\fastai\tabular\model.py", line 67, in forward
    x = [e(x_cat[:,i]) for i,e in enumerate(self.embeds)]
  File "C:\Users\analytiikka\miniconda3\envs\mlModels\lib\site-packages\fastai\tabular\model.py", line 67, in <listcomp>
    x = [e(x_cat[:,i]) for i,e in enumerate(self.embeds)]
  File "C:\Users\analytiikka\miniconda3\envs\mlModels\lib\site-packages\torch\nn\modules\module.py", line 1501, in _call_impl
    return forward_call(*args, **kwargs)
  File "C:\Users\analytiikka\miniconda3\envs\mlModels\lib\site-packages\torch\nn\modules\sparse.py", line 162, in forward
    return F.embedding(
  File "C:\Users\analytiikka\miniconda3\envs\mlModels\lib\site-packages\torch\nn\functional.py", line 2210, in embedding
    return torch.embedding(weight, input, padding_idx, scale_grad_by_freq, sparse)
RuntimeError: Expected tensor for argument #1 'indices' to have one of the following scalar types: Long, Int; but got torch.FloatTensor instead (while checking arguments for embedding)
