2023-08-16 10:23:50,258 - INFO - __main__ : 41 - Logging enabled
2023-08-16 10:23:50,288 - INFO - __main__ : 323 - *** Running server in insecure mode on port: 50052 ***
2023-08-16 10:23:53,008 - INFO - __main__ : 227 - GetCapabilities
2023-08-16 10:23:53,018 - INFO - __main__ : 250 - Adding to capabilities: SumOfRows(['col1', 'col2'])
2023-08-16 10:23:53,018 - INFO - __main__ : 250 - Adding to capabilities: SumOfColumn(['col1'])
2023-08-16 10:23:53,018 - INFO - __main__ : 250 - Adding to capabilities: MaxOfColumns_2(['col1', 'col2'])
2023-08-16 10:23:53,018 - INFO - __main__ : 250 - Adding to capabilities: RandomForest(['col1'])
2023-08-16 10:24:03,207 - INFO - __main__ : 264 - ExecuteFunction (functionId: 3)
2023-08-16 10:25:03,198 - INFO - __main__ : 41 - Logging enabled
2023-08-16 10:25:03,206 - INFO - __main__ : 323 - *** Running server in insecure mode on port: 50052 ***
2023-08-16 10:25:04,587 - INFO - __main__ : 227 - GetCapabilities
2023-08-16 10:25:04,587 - INFO - __main__ : 250 - Adding to capabilities: SumOfRows(['col1', 'col2'])
2023-08-16 10:25:04,587 - INFO - __main__ : 250 - Adding to capabilities: SumOfColumn(['col1'])
2023-08-16 10:25:04,587 - INFO - __main__ : 250 - Adding to capabilities: MaxOfColumns_2(['col1', 'col2'])
2023-08-16 10:25:04,587 - INFO - __main__ : 250 - Adding to capabilities: RandomForest(['col1'])
2023-08-16 10:25:07,968 - INFO - __main__ : 264 - ExecuteFunction (functionId: 3)
2023-08-16 10:27:55,325 - INFO - __main__ : 45 - Logging enabled
2023-08-16 10:27:55,330 - INFO - __main__ : 354 - *** Running server in insecure mode on port: 50052 ***
2023-08-16 10:27:58,168 - INFO - __main__ : 245 - GetCapabilities
2023-08-16 10:27:58,168 - INFO - __main__ : 270 - Adding to capabilities: SumOfRows(['col1', 'col2'])
2023-08-16 10:27:58,168 - INFO - __main__ : 270 - Adding to capabilities: SumOfColumn(['col1'])
2023-08-16 10:27:58,168 - INFO - __main__ : 270 - Adding to capabilities: MaxOfColumns_2(['col1', 'col2'])
2023-08-16 10:27:58,168 - INFO - __main__ : 270 - Adding to capabilities: RandomForest(['col1'])
2023-08-16 10:28:00,159 - INFO - __main__ : 287 - ExecuteFunction (functionId: 3)
2023-08-16 10:28:00,178 - ERROR - _server : 471 - Exception iterating responses: 0
Traceback (most recent call last):
  File "C:\Users\analytiikka\miniconda3\envs\mlModels\lib\site-packages\pandas\core\indexes\base.py", line 3621, in get_loc
    return self._engine.get_loc(casted_key)
  File "pandas\_libs\index.pyx", line 136, in pandas._libs.index.IndexEngine.get_loc
  File "pandas\_libs\index.pyx", line 163, in pandas._libs.index.IndexEngine.get_loc
  File "pandas\_libs\hashtable_class_helper.pxi", line 5198, in pandas._libs.hashtable.PyObjectHashTable.get_item
  File "pandas\_libs\hashtable_class_helper.pxi", line 5206, in pandas._libs.hashtable.PyObjectHashTable.get_item
KeyError: 0

The above exception was the direct cause of the following exception:

Traceback (most recent call last):
  File "C:\Users\analytiikka\miniconda3\envs\mlModels\lib\site-packages\grpc\_server.py", line 461, in _take_response_from_response_iterator
    return next(response_iterator), True
  File "__main__.py", line 130, in _random_forest
    features = exportCSV[0].toList()
  File "C:\Users\analytiikka\miniconda3\envs\mlModels\lib\site-packages\pandas\core\frame.py", line 3505, in __getitem__
    indexer = self.columns.get_loc(key)
  File "C:\Users\analytiikka\miniconda3\envs\mlModels\lib\site-packages\pandas\core\indexes\base.py", line 3623, in get_loc
    raise KeyError(key) from err
KeyError: 0
2023-08-16 10:28:00,187 - INFO - __main__ : 287 - ExecuteFunction (functionId: 3)
2023-08-16 10:28:00,198 - ERROR - _server : 471 - Exception iterating responses: 0
Traceback (most recent call last):
  File "C:\Users\analytiikka\miniconda3\envs\mlModels\lib\site-packages\pandas\core\indexes\base.py", line 3621, in get_loc
    return self._engine.get_loc(casted_key)
  File "pandas\_libs\index.pyx", line 136, in pandas._libs.index.IndexEngine.get_loc
  File "pandas\_libs\index.pyx", line 163, in pandas._libs.index.IndexEngine.get_loc
  File "pandas\_libs\hashtable_class_helper.pxi", line 5198, in pandas._libs.hashtable.PyObjectHashTable.get_item
  File "pandas\_libs\hashtable_class_helper.pxi", line 5206, in pandas._libs.hashtable.PyObjectHashTable.get_item
KeyError: 0

The above exception was the direct cause of the following exception:

Traceback (most recent call last):
  File "C:\Users\analytiikka\miniconda3\envs\mlModels\lib\site-packages\grpc\_server.py", line 461, in _take_response_from_response_iterator
    return next(response_iterator), True
  File "__main__.py", line 130, in _random_forest
    features = exportCSV[0].toList()
  File "C:\Users\analytiikka\miniconda3\envs\mlModels\lib\site-packages\pandas\core\frame.py", line 3505, in __getitem__
    indexer = self.columns.get_loc(key)
  File "C:\Users\analytiikka\miniconda3\envs\mlModels\lib\site-packages\pandas\core\indexes\base.py", line 3623, in get_loc
    raise KeyError(key) from err
KeyError: 0
2023-08-16 10:28:00,208 - INFO - __main__ : 287 - ExecuteFunction (functionId: 3)
2023-08-16 10:28:00,211 - ERROR - _server : 471 - Exception iterating responses: 0
Traceback (most recent call last):
  File "C:\Users\analytiikka\miniconda3\envs\mlModels\lib\site-packages\pandas\core\indexes\base.py", line 3621, in get_loc
    return self._engine.get_loc(casted_key)
  File "pandas\_libs\index.pyx", line 136, in pandas._libs.index.IndexEngine.get_loc
  File "pandas\_libs\index.pyx", line 163, in pandas._libs.index.IndexEngine.get_loc
  File "pandas\_libs\hashtable_class_helper.pxi", line 5198, in pandas._libs.hashtable.PyObjectHashTable.get_item
  File "pandas\_libs\hashtable_class_helper.pxi", line 5206, in pandas._libs.hashtable.PyObjectHashTable.get_item
KeyError: 0

The above exception was the direct cause of the following exception:

Traceback (most recent call last):
  File "C:\Users\analytiikka\miniconda3\envs\mlModels\lib\site-packages\grpc\_server.py", line 461, in _take_response_from_response_iterator
    return next(response_iterator), True
  File "__main__.py", line 130, in _random_forest
    features = exportCSV[0].toList()
  File "C:\Users\analytiikka\miniconda3\envs\mlModels\lib\site-packages\pandas\core\frame.py", line 3505, in __getitem__
    indexer = self.columns.get_loc(key)
  File "C:\Users\analytiikka\miniconda3\envs\mlModels\lib\site-packages\pandas\core\indexes\base.py", line 3623, in get_loc
    raise KeyError(key) from err
KeyError: 0
2023-08-16 10:28:00,217 - INFO - __main__ : 287 - ExecuteFunction (functionId: 3)
2023-08-16 10:28:00,228 - ERROR - _server : 471 - Exception iterating responses: 0
Traceback (most recent call last):
  File "C:\Users\analytiikka\miniconda3\envs\mlModels\lib\site-packages\pandas\core\indexes\base.py", line 3621, in get_loc
    return self._engine.get_loc(casted_key)
  File "pandas\_libs\index.pyx", line 136, in pandas._libs.index.IndexEngine.get_loc
  File "pandas\_libs\index.pyx", line 163, in pandas._libs.index.IndexEngine.get_loc
  File "pandas\_libs\hashtable_class_helper.pxi", line 5198, in pandas._libs.hashtable.PyObjectHashTable.get_item
  File "pandas\_libs\hashtable_class_helper.pxi", line 5206, in pandas._libs.hashtable.PyObjectHashTable.get_item
KeyError: 0

The above exception was the direct cause of the following exception:

Traceback (most recent call last):
  File "C:\Users\analytiikka\miniconda3\envs\mlModels\lib\site-packages\grpc\_server.py", line 461, in _take_response_from_response_iterator
    return next(response_iterator), True
  File "__main__.py", line 130, in _random_forest
    features = exportCSV[0].toList()
  File "C:\Users\analytiikka\miniconda3\envs\mlModels\lib\site-packages\pandas\core\frame.py", line 3505, in __getitem__
    indexer = self.columns.get_loc(key)
  File "C:\Users\analytiikka\miniconda3\envs\mlModels\lib\site-packages\pandas\core\indexes\base.py", line 3623, in get_loc
    raise KeyError(key) from err
KeyError: 0
2023-08-16 10:28:03,787 - INFO - __main__ : 287 - ExecuteFunction (functionId: 3)
2023-08-16 10:28:03,808 - ERROR - _server : 471 - Exception iterating responses: 0
Traceback (most recent call last):
  File "C:\Users\analytiikka\miniconda3\envs\mlModels\lib\site-packages\pandas\core\indexes\base.py", line 3621, in get_loc
    return self._engine.get_loc(casted_key)
  File "pandas\_libs\index.pyx", line 136, in pandas._libs.index.IndexEngine.get_loc
  File "pandas\_libs\index.pyx", line 163, in pandas._libs.index.IndexEngine.get_loc
  File "pandas\_libs\hashtable_class_helper.pxi", line 5198, in pandas._libs.hashtable.PyObjectHashTable.get_item
  File "pandas\_libs\hashtable_class_helper.pxi", line 5206, in pandas._libs.hashtable.PyObjectHashTable.get_item
KeyError: 0

The above exception was the direct cause of the following exception:

Traceback (most recent call last):
  File "C:\Users\analytiikka\miniconda3\envs\mlModels\lib\site-packages\grpc\_server.py", line 461, in _take_response_from_response_iterator
    return next(response_iterator), True
  File "__main__.py", line 130, in _random_forest
    features = exportCSV[0].toList()
  File "C:\Users\analytiikka\miniconda3\envs\mlModels\lib\site-packages\pandas\core\frame.py", line 3505, in __getitem__
    indexer = self.columns.get_loc(key)
  File "C:\Users\analytiikka\miniconda3\envs\mlModels\lib\site-packages\pandas\core\indexes\base.py", line 3623, in get_loc
    raise KeyError(key) from err
KeyError: 0
2023-08-16 10:28:03,808 - INFO - __main__ : 287 - ExecuteFunction (functionId: 3)
2023-08-16 10:28:03,828 - ERROR - _server : 471 - Exception iterating responses: 0
Traceback (most recent call last):
  File "C:\Users\analytiikka\miniconda3\envs\mlModels\lib\site-packages\pandas\core\indexes\base.py", line 3621, in get_loc
    return self._engine.get_loc(casted_key)
  File "pandas\_libs\index.pyx", line 136, in pandas._libs.index.IndexEngine.get_loc
  File "pandas\_libs\index.pyx", line 163, in pandas._libs.index.IndexEngine.get_loc
  File "pandas\_libs\hashtable_class_helper.pxi", line 5198, in pandas._libs.hashtable.PyObjectHashTable.get_item
  File "pandas\_libs\hashtable_class_helper.pxi", line 5206, in pandas._libs.hashtable.PyObjectHashTable.get_item
KeyError: 0

The above exception was the direct cause of the following exception:

Traceback (most recent call last):
  File "C:\Users\analytiikka\miniconda3\envs\mlModels\lib\site-packages\grpc\_server.py", line 461, in _take_response_from_response_iterator
    return next(response_iterator), True
  File "__main__.py", line 130, in _random_forest
    features = exportCSV[0].toList()
  File "C:\Users\analytiikka\miniconda3\envs\mlModels\lib\site-packages\pandas\core\frame.py", line 3505, in __getitem__
    indexer = self.columns.get_loc(key)
  File "C:\Users\analytiikka\miniconda3\envs\mlModels\lib\site-packages\pandas\core\indexes\base.py", line 3623, in get_loc
    raise KeyError(key) from err
KeyError: 0
2023-08-16 10:30:03,589 - INFO - __main__ : 287 - ExecuteFunction (functionId: 3)
2023-08-16 10:30:04,175 - INFO - __main__ : 287 - ExecuteFunction (functionId: 3)
2023-08-16 10:30:04,962 - INFO - __main__ : 287 - ExecuteFunction (functionId: 3)
2023-08-16 10:30:05,756 - INFO - __main__ : 287 - ExecuteFunction (functionId: 3)
2023-08-16 10:31:01,749 - ERROR - _server : 471 - Exception iterating responses: 0
Traceback (most recent call last):
  File "C:\Users\analytiikka\miniconda3\envs\mlModels\lib\site-packages\pandas\core\indexes\base.py", line 3621, in get_loc
    return self._engine.get_loc(casted_key)
  File "pandas\_libs\index.pyx", line 136, in pandas._libs.index.IndexEngine.get_loc
  File "pandas\_libs\index.pyx", line 163, in pandas._libs.index.IndexEngine.get_loc
  File "pandas\_libs\hashtable_class_helper.pxi", line 5198, in pandas._libs.hashtable.PyObjectHashTable.get_item
  File "pandas\_libs\hashtable_class_helper.pxi", line 5206, in pandas._libs.hashtable.PyObjectHashTable.get_item
KeyError: 0

The above exception was the direct cause of the following exception:

Traceback (most recent call last):
  File "C:\Users\analytiikka\miniconda3\envs\mlModels\lib\site-packages\grpc\_server.py", line 461, in _take_response_from_response_iterator
    return next(response_iterator), True
  File "__main__.py", line 130, in _random_forest
    features = exportCSV[0].toList()
  File "C:\Users\analytiikka\miniconda3\envs\mlModels\lib\site-packages\pandas\core\frame.py", line 3505, in __getitem__
    indexer = self.columns.get_loc(key)
  File "C:\Users\analytiikka\miniconda3\envs\mlModels\lib\site-packages\pandas\core\indexes\base.py", line 3623, in get_loc
    raise KeyError(key) from err
KeyError: 0
2023-08-16 10:31:01,759 - INFO - __main__ : 287 - ExecuteFunction (functionId: 3)
2023-08-16 10:31:01,787 - ERROR - _server : 471 - Exception iterating responses: 0
Traceback (most recent call last):
  File "C:\Users\analytiikka\miniconda3\envs\mlModels\lib\site-packages\pandas\core\indexes\base.py", line 3621, in get_loc
    return self._engine.get_loc(casted_key)
  File "pandas\_libs\index.pyx", line 136, in pandas._libs.index.IndexEngine.get_loc
  File "pandas\_libs\index.pyx", line 163, in pandas._libs.index.IndexEngine.get_loc
  File "pandas\_libs\hashtable_class_helper.pxi", line 5198, in pandas._libs.hashtable.PyObjectHashTable.get_item
  File "pandas\_libs\hashtable_class_helper.pxi", line 5206, in pandas._libs.hashtable.PyObjectHashTable.get_item
KeyError: 0

The above exception was the direct cause of the following exception:

Traceback (most recent call last):
  File "C:\Users\analytiikka\miniconda3\envs\mlModels\lib\site-packages\grpc\_server.py", line 461, in _take_response_from_response_iterator
    return next(response_iterator), True
  File "__main__.py", line 130, in _random_forest
    features = exportCSV[0].toList()
  File "C:\Users\analytiikka\miniconda3\envs\mlModels\lib\site-packages\pandas\core\frame.py", line 3505, in __getitem__
    indexer = self.columns.get_loc(key)
  File "C:\Users\analytiikka\miniconda3\envs\mlModels\lib\site-packages\pandas\core\indexes\base.py", line 3623, in get_loc
    raise KeyError(key) from err
KeyError: 0
2023-08-16 10:31:01,788 - INFO - __main__ : 287 - ExecuteFunction (functionId: 3)
2023-08-16 10:31:01,807 - ERROR - _server : 471 - Exception iterating responses: 0
Traceback (most recent call last):
  File "C:\Users\analytiikka\miniconda3\envs\mlModels\lib\site-packages\pandas\core\indexes\base.py", line 3621, in get_loc
    return self._engine.get_loc(casted_key)
  File "pandas\_libs\index.pyx", line 136, in pandas._libs.index.IndexEngine.get_loc
  File "pandas\_libs\index.pyx", line 163, in pandas._libs.index.IndexEngine.get_loc
  File "pandas\_libs\hashtable_class_helper.pxi", line 5198, in pandas._libs.hashtable.PyObjectHashTable.get_item
  File "pandas\_libs\hashtable_class_helper.pxi", line 5206, in pandas._libs.hashtable.PyObjectHashTable.get_item
KeyError: 0

The above exception was the direct cause of the following exception:

Traceback (most recent call last):
  File "C:\Users\analytiikka\miniconda3\envs\mlModels\lib\site-packages\grpc\_server.py", line 461, in _take_response_from_response_iterator
    return next(response_iterator), True
  File "__main__.py", line 130, in _random_forest
    features = exportCSV[0].toList()
  File "C:\Users\analytiikka\miniconda3\envs\mlModels\lib\site-packages\pandas\core\frame.py", line 3505, in __getitem__
    indexer = self.columns.get_loc(key)
  File "C:\Users\analytiikka\miniconda3\envs\mlModels\lib\site-packages\pandas\core\indexes\base.py", line 3623, in get_loc
    raise KeyError(key) from err
KeyError: 0
2023-08-16 10:31:01,808 - INFO - __main__ : 287 - ExecuteFunction (functionId: 3)
2023-08-16 10:31:01,818 - ERROR - _server : 471 - Exception iterating responses: 0
Traceback (most recent call last):
  File "C:\Users\analytiikka\miniconda3\envs\mlModels\lib\site-packages\pandas\core\indexes\base.py", line 3621, in get_loc
    return self._engine.get_loc(casted_key)
  File "pandas\_libs\index.pyx", line 136, in pandas._libs.index.IndexEngine.get_loc
  File "pandas\_libs\index.pyx", line 163, in pandas._libs.index.IndexEngine.get_loc
  File "pandas\_libs\hashtable_class_helper.pxi", line 5198, in pandas._libs.hashtable.PyObjectHashTable.get_item
  File "pandas\_libs\hashtable_class_helper.pxi", line 5206, in pandas._libs.hashtable.PyObjectHashTable.get_item
KeyError: 0

The above exception was the direct cause of the following exception:

Traceback (most recent call last):
  File "C:\Users\analytiikka\miniconda3\envs\mlModels\lib\site-packages\grpc\_server.py", line 461, in _take_response_from_response_iterator
    return next(response_iterator), True
  File "__main__.py", line 130, in _random_forest
    features = exportCSV[0].toList()
  File "C:\Users\analytiikka\miniconda3\envs\mlModels\lib\site-packages\pandas\core\frame.py", line 3505, in __getitem__
    indexer = self.columns.get_loc(key)
  File "C:\Users\analytiikka\miniconda3\envs\mlModels\lib\site-packages\pandas\core\indexes\base.py", line 3623, in get_loc
    raise KeyError(key) from err
KeyError: 0
2023-08-16 10:34:04,749 - INFO - __main__ : 45 - Logging enabled
2023-08-16 10:34:04,749 - INFO - __main__ : 354 - *** Running server in insecure mode on port: 50052 ***
2023-08-16 10:34:05,250 - INFO - __main__ : 245 - GetCapabilities
2023-08-16 10:34:05,256 - INFO - __main__ : 270 - Adding to capabilities: SumOfRows(['col1', 'col2'])
2023-08-16 10:34:05,257 - INFO - __main__ : 270 - Adding to capabilities: SumOfColumn(['col1'])
2023-08-16 10:34:05,257 - INFO - __main__ : 270 - Adding to capabilities: MaxOfColumns_2(['col1', 'col2'])
2023-08-16 10:34:05,259 - INFO - __main__ : 270 - Adding to capabilities: RandomForest(['col1'])
2023-08-16 10:34:13,018 - INFO - __main__ : 245 - GetCapabilities
2023-08-16 10:34:13,018 - INFO - __main__ : 270 - Adding to capabilities: SumOfRows(['col1', 'col2'])
2023-08-16 10:34:13,018 - INFO - __main__ : 270 - Adding to capabilities: SumOfColumn(['col1'])
2023-08-16 10:34:13,018 - INFO - __main__ : 270 - Adding to capabilities: MaxOfColumns_2(['col1', 'col2'])
2023-08-16 10:34:13,018 - INFO - __main__ : 270 - Adding to capabilities: RandomForest(['col1'])
2023-08-16 10:34:20,168 - INFO - __main__ : 287 - ExecuteFunction (functionId: 3)
2023-08-16 10:34:20,178 - ERROR - _server : 471 - Exception iterating responses: 'Series' object has no attribute 'toList'
Traceback (most recent call last):
  File "C:\Users\analytiikka\miniconda3\envs\mlModels\lib\site-packages\grpc\_server.py", line 461, in _take_response_from_response_iterator
    return next(response_iterator), True
  File "__main__.py", line 130, in _random_forest
    features = exportCSV.iloc[0].toList()
  File "C:\Users\analytiikka\miniconda3\envs\mlModels\lib\site-packages\pandas\core\generic.py", line 5575, in __getattr__
    return object.__getattribute__(self, name)
AttributeError: 'Series' object has no attribute 'toList'
2023-08-16 10:34:20,178 - INFO - __main__ : 287 - ExecuteFunction (functionId: 3)
2023-08-16 10:34:20,191 - ERROR - _server : 471 - Exception iterating responses: 'Series' object has no attribute 'toList'
Traceback (most recent call last):
  File "C:\Users\analytiikka\miniconda3\envs\mlModels\lib\site-packages\grpc\_server.py", line 461, in _take_response_from_response_iterator
    return next(response_iterator), True
  File "__main__.py", line 130, in _random_forest
    features = exportCSV.iloc[0].toList()
  File "C:\Users\analytiikka\miniconda3\envs\mlModels\lib\site-packages\pandas\core\generic.py", line 5575, in __getattr__
    return object.__getattribute__(self, name)
AttributeError: 'Series' object has no attribute 'toList'
2023-08-16 10:34:20,197 - INFO - __main__ : 287 - ExecuteFunction (functionId: 3)
2023-08-16 10:34:20,208 - ERROR - _server : 471 - Exception iterating responses: 'Series' object has no attribute 'toList'
Traceback (most recent call last):
  File "C:\Users\analytiikka\miniconda3\envs\mlModels\lib\site-packages\grpc\_server.py", line 461, in _take_response_from_response_iterator
    return next(response_iterator), True
  File "__main__.py", line 130, in _random_forest
    features = exportCSV.iloc[0].toList()
  File "C:\Users\analytiikka\miniconda3\envs\mlModels\lib\site-packages\pandas\core\generic.py", line 5575, in __getattr__
    return object.__getattribute__(self, name)
AttributeError: 'Series' object has no attribute 'toList'
2023-08-16 10:34:20,208 - INFO - __main__ : 287 - ExecuteFunction (functionId: 3)
2023-08-16 10:34:20,227 - ERROR - _server : 471 - Exception iterating responses: 'Series' object has no attribute 'toList'
Traceback (most recent call last):
  File "C:\Users\analytiikka\miniconda3\envs\mlModels\lib\site-packages\grpc\_server.py", line 461, in _take_response_from_response_iterator
    return next(response_iterator), True
  File "__main__.py", line 130, in _random_forest
    features = exportCSV.iloc[0].toList()
  File "C:\Users\analytiikka\miniconda3\envs\mlModels\lib\site-packages\pandas\core\generic.py", line 5575, in __getattr__
    return object.__getattribute__(self, name)
AttributeError: 'Series' object has no attribute 'toList'
2023-08-16 10:34:23,158 - INFO - __main__ : 287 - ExecuteFunction (functionId: 3)
2023-08-16 10:34:23,177 - ERROR - _server : 471 - Exception iterating responses: 'Series' object has no attribute 'toList'
Traceback (most recent call last):
  File "C:\Users\analytiikka\miniconda3\envs\mlModels\lib\site-packages\grpc\_server.py", line 461, in _take_response_from_response_iterator
    return next(response_iterator), True
  File "__main__.py", line 130, in _random_forest
    features = exportCSV.iloc[0].toList()
  File "C:\Users\analytiikka\miniconda3\envs\mlModels\lib\site-packages\pandas\core\generic.py", line 5575, in __getattr__
    return object.__getattribute__(self, name)
AttributeError: 'Series' object has no attribute 'toList'
2023-08-16 10:34:23,178 - INFO - __main__ : 287 - ExecuteFunction (functionId: 3)
2023-08-16 10:34:23,189 - ERROR - _server : 471 - Exception iterating responses: 'Series' object has no attribute 'toList'
Traceback (most recent call last):
  File "C:\Users\analytiikka\miniconda3\envs\mlModels\lib\site-packages\grpc\_server.py", line 461, in _take_response_from_response_iterator
    return next(response_iterator), True
  File "__main__.py", line 130, in _random_forest
    features = exportCSV.iloc[0].toList()
  File "C:\Users\analytiikka\miniconda3\envs\mlModels\lib\site-packages\pandas\core\generic.py", line 5575, in __getattr__
    return object.__getattribute__(self, name)
AttributeError: 'Series' object has no attribute 'toList'
2023-08-16 10:36:16,059 - INFO - __main__ : 45 - Logging enabled
2023-08-16 10:36:16,059 - INFO - __main__ : 354 - *** Running server in insecure mode on port: 50052 ***
2023-08-16 10:36:16,261 - INFO - __main__ : 245 - GetCapabilities
2023-08-16 10:36:16,261 - INFO - __main__ : 270 - Adding to capabilities: SumOfRows(['col1', 'col2'])
2023-08-16 10:36:16,261 - INFO - __main__ : 270 - Adding to capabilities: SumOfColumn(['col1'])
2023-08-16 10:36:16,261 - INFO - __main__ : 270 - Adding to capabilities: MaxOfColumns_2(['col1', 'col2'])
2023-08-16 10:36:16,261 - INFO - __main__ : 270 - Adding to capabilities: RandomForest(['col1'])
2023-08-16 10:36:17,799 - INFO - __main__ : 287 - ExecuteFunction (functionId: 3)
2023-08-16 10:36:17,820 - ERROR - _server : 471 - Exception iterating responses: "None of [Index(['survived'], dtype='object')] are in the [columns]"
Traceback (most recent call last):
  File "C:\Users\analytiikka\miniconda3\envs\mlModels\lib\site-packages\grpc\_server.py", line 461, in _take_response_from_response_iterator
    return next(response_iterator), True
  File "__main__.py", line 136, in _random_forest
    to = TabularPandas(
  File "C:\Users\analytiikka\miniconda3\envs\mlModels\lib\site-packages\fastai\tabular\core.py", line 160, in __init__
    ys = df[self.y_names]
  File "C:\Users\analytiikka\miniconda3\envs\mlModels\lib\site-packages\pandas\core\frame.py", line 3511, in __getitem__
    indexer = self.columns._get_indexer_strict(key, "columns")[1]
  File "C:\Users\analytiikka\miniconda3\envs\mlModels\lib\site-packages\pandas\core\indexes\base.py", line 5782, in _get_indexer_strict
    self._raise_if_missing(keyarr, indexer, axis_name)
  File "C:\Users\analytiikka\miniconda3\envs\mlModels\lib\site-packages\pandas\core\indexes\base.py", line 5842, in _raise_if_missing
    raise KeyError(f"None of [{key}] are in the [{axis_name}]")
KeyError: "None of [Index(['survived'], dtype='object')] are in the [columns]"
2023-08-16 10:36:17,829 - INFO - __main__ : 287 - ExecuteFunction (functionId: 3)
2023-08-16 10:36:17,848 - ERROR - _server : 471 - Exception iterating responses: "None of [Index(['survived'], dtype='object')] are in the [columns]"
Traceback (most recent call last):
  File "C:\Users\analytiikka\miniconda3\envs\mlModels\lib\site-packages\grpc\_server.py", line 461, in _take_response_from_response_iterator
    return next(response_iterator), True
  File "__main__.py", line 136, in _random_forest
    to = TabularPandas(
  File "C:\Users\analytiikka\miniconda3\envs\mlModels\lib\site-packages\fastai\tabular\core.py", line 160, in __init__
    ys = df[self.y_names]
  File "C:\Users\analytiikka\miniconda3\envs\mlModels\lib\site-packages\pandas\core\frame.py", line 3511, in __getitem__
    indexer = self.columns._get_indexer_strict(key, "columns")[1]
  File "C:\Users\analytiikka\miniconda3\envs\mlModels\lib\site-packages\pandas\core\indexes\base.py", line 5782, in _get_indexer_strict
    self._raise_if_missing(keyarr, indexer, axis_name)
  File "C:\Users\analytiikka\miniconda3\envs\mlModels\lib\site-packages\pandas\core\indexes\base.py", line 5842, in _raise_if_missing
    raise KeyError(f"None of [{key}] are in the [{axis_name}]")
KeyError: "None of [Index(['survived'], dtype='object')] are in the [columns]"
2023-08-16 10:36:17,850 - INFO - __main__ : 287 - ExecuteFunction (functionId: 3)
2023-08-16 10:36:17,863 - ERROR - _server : 471 - Exception iterating responses: "None of [Index(['survived'], dtype='object')] are in the [columns]"
Traceback (most recent call last):
  File "C:\Users\analytiikka\miniconda3\envs\mlModels\lib\site-packages\grpc\_server.py", line 461, in _take_response_from_response_iterator
    return next(response_iterator), True
  File "__main__.py", line 136, in _random_forest
    to = TabularPandas(
  File "C:\Users\analytiikka\miniconda3\envs\mlModels\lib\site-packages\fastai\tabular\core.py", line 160, in __init__
    ys = df[self.y_names]
  File "C:\Users\analytiikka\miniconda3\envs\mlModels\lib\site-packages\pandas\core\frame.py", line 3511, in __getitem__
    indexer = self.columns._get_indexer_strict(key, "columns")[1]
  File "C:\Users\analytiikka\miniconda3\envs\mlModels\lib\site-packages\pandas\core\indexes\base.py", line 5782, in _get_indexer_strict
    self._raise_if_missing(keyarr, indexer, axis_name)
  File "C:\Users\analytiikka\miniconda3\envs\mlModels\lib\site-packages\pandas\core\indexes\base.py", line 5842, in _raise_if_missing
    raise KeyError(f"None of [{key}] are in the [{axis_name}]")
KeyError: "None of [Index(['survived'], dtype='object')] are in the [columns]"
2023-08-16 10:36:17,868 - INFO - __main__ : 287 - ExecuteFunction (functionId: 3)
2023-08-16 10:36:17,880 - ERROR - _server : 471 - Exception iterating responses: "None of [Index(['survived'], dtype='object')] are in the [columns]"
Traceback (most recent call last):
  File "C:\Users\analytiikka\miniconda3\envs\mlModels\lib\site-packages\grpc\_server.py", line 461, in _take_response_from_response_iterator
    return next(response_iterator), True
  File "__main__.py", line 136, in _random_forest
    to = TabularPandas(
  File "C:\Users\analytiikka\miniconda3\envs\mlModels\lib\site-packages\fastai\tabular\core.py", line 160, in __init__
    ys = df[self.y_names]
  File "C:\Users\analytiikka\miniconda3\envs\mlModels\lib\site-packages\pandas\core\frame.py", line 3511, in __getitem__
    indexer = self.columns._get_indexer_strict(key, "columns")[1]
  File "C:\Users\analytiikka\miniconda3\envs\mlModels\lib\site-packages\pandas\core\indexes\base.py", line 5782, in _get_indexer_strict
    self._raise_if_missing(keyarr, indexer, axis_name)
  File "C:\Users\analytiikka\miniconda3\envs\mlModels\lib\site-packages\pandas\core\indexes\base.py", line 5842, in _raise_if_missing
    raise KeyError(f"None of [{key}] are in the [{axis_name}]")
KeyError: "None of [Index(['survived'], dtype='object')] are in the [columns]"
2023-08-16 10:36:21,700 - INFO - __main__ : 287 - ExecuteFunction (functionId: 3)
2023-08-16 10:36:21,719 - ERROR - _server : 471 - Exception iterating responses: "None of [Index(['survived'], dtype='object')] are in the [columns]"
Traceback (most recent call last):
  File "C:\Users\analytiikka\miniconda3\envs\mlModels\lib\site-packages\grpc\_server.py", line 461, in _take_response_from_response_iterator
    return next(response_iterator), True
  File "__main__.py", line 136, in _random_forest
    to = TabularPandas(
  File "C:\Users\analytiikka\miniconda3\envs\mlModels\lib\site-packages\fastai\tabular\core.py", line 160, in __init__
    ys = df[self.y_names]
  File "C:\Users\analytiikka\miniconda3\envs\mlModels\lib\site-packages\pandas\core\frame.py", line 3511, in __getitem__
    indexer = self.columns._get_indexer_strict(key, "columns")[1]
  File "C:\Users\analytiikka\miniconda3\envs\mlModels\lib\site-packages\pandas\core\indexes\base.py", line 5782, in _get_indexer_strict
    self._raise_if_missing(keyarr, indexer, axis_name)
  File "C:\Users\analytiikka\miniconda3\envs\mlModels\lib\site-packages\pandas\core\indexes\base.py", line 5842, in _raise_if_missing
    raise KeyError(f"None of [{key}] are in the [{axis_name}]")
KeyError: "None of [Index(['survived'], dtype='object')] are in the [columns]"
2023-08-16 10:36:21,729 - INFO - __main__ : 287 - ExecuteFunction (functionId: 3)
2023-08-16 10:36:21,740 - ERROR - _server : 471 - Exception iterating responses: "None of [Index(['survived'], dtype='object')] are in the [columns]"
Traceback (most recent call last):
  File "C:\Users\analytiikka\miniconda3\envs\mlModels\lib\site-packages\grpc\_server.py", line 461, in _take_response_from_response_iterator
    return next(response_iterator), True
  File "__main__.py", line 136, in _random_forest
    to = TabularPandas(
  File "C:\Users\analytiikka\miniconda3\envs\mlModels\lib\site-packages\fastai\tabular\core.py", line 160, in __init__
    ys = df[self.y_names]
  File "C:\Users\analytiikka\miniconda3\envs\mlModels\lib\site-packages\pandas\core\frame.py", line 3511, in __getitem__
    indexer = self.columns._get_indexer_strict(key, "columns")[1]
  File "C:\Users\analytiikka\miniconda3\envs\mlModels\lib\site-packages\pandas\core\indexes\base.py", line 5782, in _get_indexer_strict
    self._raise_if_missing(keyarr, indexer, axis_name)
  File "C:\Users\analytiikka\miniconda3\envs\mlModels\lib\site-packages\pandas\core\indexes\base.py", line 5842, in _raise_if_missing
    raise KeyError(f"None of [{key}] are in the [{axis_name}]")
KeyError: "None of [Index(['survived'], dtype='object')] are in the [columns]"
2023-08-16 10:37:05,459 - INFO - __main__ : 45 - Logging enabled
2023-08-16 10:37:05,470 - INFO - __main__ : 354 - *** Running server in insecure mode on port: 50052 ***
2023-08-16 10:37:05,921 - INFO - __main__ : 245 - GetCapabilities
2023-08-16 10:37:05,921 - INFO - __main__ : 270 - Adding to capabilities: SumOfRows(['col1', 'col2'])
2023-08-16 10:37:05,928 - INFO - __main__ : 270 - Adding to capabilities: SumOfColumn(['col1'])
2023-08-16 10:37:05,929 - INFO - __main__ : 270 - Adding to capabilities: MaxOfColumns_2(['col1', 'col2'])
2023-08-16 10:37:05,930 - INFO - __main__ : 270 - Adding to capabilities: RandomForest(['col1'])
2023-08-16 10:37:12,017 - INFO - __main__ : 287 - ExecuteFunction (functionId: 3)
2023-08-16 10:37:12,040 - ERROR - _server : 471 - Exception iterating responses: "None of [Index([22.0, 'S', 7.25, 0, 3, 'male', 1, 0], dtype='object')] are in the [columns]"
Traceback (most recent call last):
  File "C:\Users\analytiikka\miniconda3\envs\mlModels\lib\site-packages\grpc\_server.py", line 461, in _take_response_from_response_iterator
    return next(response_iterator), True
  File "__main__.py", line 136, in _random_forest
    to = TabularPandas(
  File "C:\Users\analytiikka\miniconda3\envs\mlModels\lib\site-packages\fastai\tabular\core.py", line 168, in __init__
    if do_setup: self.setup()
  File "C:\Users\analytiikka\miniconda3\envs\mlModels\lib\site-packages\fastai\tabular\core.py", line 179, in setup
    def setup(self): self.procs.setup(self)
  File "C:\Users\analytiikka\miniconda3\envs\mlModels\lib\site-packages\fastcore\transform.py", line 200, in setup
    for t in tfms: self.add(t,items, train_setup)
  File "C:\Users\analytiikka\miniconda3\envs\mlModels\lib\site-packages\fastcore\transform.py", line 204, in add
    for t in ts: t.setup(items, train_setup)
  File "C:\Users\analytiikka\miniconda3\envs\mlModels\lib\site-packages\fastai\tabular\core.py", line 224, in setup
    super().setup(getattr(items,'train',items), train_setup=False)
  File "C:\Users\analytiikka\miniconda3\envs\mlModels\lib\site-packages\fastcore\transform.py", line 87, in setup
    return self.setups(getattr(items, 'train', items) if train_setup else items)
  File "C:\Users\analytiikka\miniconda3\envs\mlModels\lib\site-packages\fastcore\dispatch.py", line 120, in __call__
    return f(*args, **kwargs)
  File "C:\Users\analytiikka\miniconda3\envs\mlModels\lib\site-packages\fastai\tabular\core.py", line 302, in setups
    missing = pd.isnull(to.conts).any()
  File "C:\Users\analytiikka\miniconda3\envs\mlModels\lib\site-packages\fastai\tabular\core.py", line 208, in f
    def f(o): return o[list(getattr(o,nm+'_names'))]
  File "C:\Users\analytiikka\miniconda3\envs\mlModels\lib\site-packages\fastcore\foundation.py", line 88, in __getitem__
    def __getitem__(self, k): return self.items[list(k) if isinstance(k,CollBase) else k]
  File "C:\Users\analytiikka\miniconda3\envs\mlModels\lib\site-packages\pandas\core\frame.py", line 3511, in __getitem__
    indexer = self.columns._get_indexer_strict(key, "columns")[1]
  File "C:\Users\analytiikka\miniconda3\envs\mlModels\lib\site-packages\pandas\core\indexes\base.py", line 5782, in _get_indexer_strict
    self._raise_if_missing(keyarr, indexer, axis_name)
  File "C:\Users\analytiikka\miniconda3\envs\mlModels\lib\site-packages\pandas\core\indexes\base.py", line 5842, in _raise_if_missing
    raise KeyError(f"None of [{key}] are in the [{axis_name}]")
KeyError: "None of [Index([22.0, 'S', 7.25, 0, 3, 'male', 1, 0], dtype='object')] are in the [columns]"
2023-08-16 10:37:12,053 - INFO - __main__ : 287 - ExecuteFunction (functionId: 3)
2023-08-16 10:37:12,069 - ERROR - _server : 471 - Exception iterating responses: "None of [Index([22.0, 'S', 7.25, 0, 3, 'male', 1, 0], dtype='object')] are in the [columns]"
Traceback (most recent call last):
  File "C:\Users\analytiikka\miniconda3\envs\mlModels\lib\site-packages\grpc\_server.py", line 461, in _take_response_from_response_iterator
    return next(response_iterator), True
  File "__main__.py", line 136, in _random_forest
    to = TabularPandas(
  File "C:\Users\analytiikka\miniconda3\envs\mlModels\lib\site-packages\fastai\tabular\core.py", line 168, in __init__
    if do_setup: self.setup()
  File "C:\Users\analytiikka\miniconda3\envs\mlModels\lib\site-packages\fastai\tabular\core.py", line 179, in setup
    def setup(self): self.procs.setup(self)
  File "C:\Users\analytiikka\miniconda3\envs\mlModels\lib\site-packages\fastcore\transform.py", line 200, in setup
    for t in tfms: self.add(t,items, train_setup)
  File "C:\Users\analytiikka\miniconda3\envs\mlModels\lib\site-packages\fastcore\transform.py", line 204, in add
    for t in ts: t.setup(items, train_setup)
  File "C:\Users\analytiikka\miniconda3\envs\mlModels\lib\site-packages\fastai\tabular\core.py", line 224, in setup
    super().setup(getattr(items,'train',items), train_setup=False)
  File "C:\Users\analytiikka\miniconda3\envs\mlModels\lib\site-packages\fastcore\transform.py", line 87, in setup
    return self.setups(getattr(items, 'train', items) if train_setup else items)
  File "C:\Users\analytiikka\miniconda3\envs\mlModels\lib\site-packages\fastcore\dispatch.py", line 120, in __call__
    return f(*args, **kwargs)
  File "C:\Users\analytiikka\miniconda3\envs\mlModels\lib\site-packages\fastai\tabular\core.py", line 302, in setups
    missing = pd.isnull(to.conts).any()
  File "C:\Users\analytiikka\miniconda3\envs\mlModels\lib\site-packages\fastai\tabular\core.py", line 208, in f
    def f(o): return o[list(getattr(o,nm+'_names'))]
  File "C:\Users\analytiikka\miniconda3\envs\mlModels\lib\site-packages\fastcore\foundation.py", line 88, in __getitem__
    def __getitem__(self, k): return self.items[list(k) if isinstance(k,CollBase) else k]
  File "C:\Users\analytiikka\miniconda3\envs\mlModels\lib\site-packages\pandas\core\frame.py", line 3511, in __getitem__
    indexer = self.columns._get_indexer_strict(key, "columns")[1]
  File "C:\Users\analytiikka\miniconda3\envs\mlModels\lib\site-packages\pandas\core\indexes\base.py", line 5782, in _get_indexer_strict
    self._raise_if_missing(keyarr, indexer, axis_name)
  File "C:\Users\analytiikka\miniconda3\envs\mlModels\lib\site-packages\pandas\core\indexes\base.py", line 5842, in _raise_if_missing
    raise KeyError(f"None of [{key}] are in the [{axis_name}]")
KeyError: "None of [Index([22.0, 'S', 7.25, 0, 3, 'male', 1, 0], dtype='object')] are in the [columns]"
2023-08-16 10:37:12,070 - INFO - __main__ : 287 - ExecuteFunction (functionId: 3)
2023-08-16 10:37:12,088 - ERROR - _server : 471 - Exception iterating responses: "None of [Index([22.0, 'S', 7.25, 0, 3, 'male', 1, 0], dtype='object')] are in the [columns]"
Traceback (most recent call last):
  File "C:\Users\analytiikka\miniconda3\envs\mlModels\lib\site-packages\grpc\_server.py", line 461, in _take_response_from_response_iterator
    return next(response_iterator), True
  File "__main__.py", line 136, in _random_forest
    to = TabularPandas(
  File "C:\Users\analytiikka\miniconda3\envs\mlModels\lib\site-packages\fastai\tabular\core.py", line 168, in __init__
    if do_setup: self.setup()
  File "C:\Users\analytiikka\miniconda3\envs\mlModels\lib\site-packages\fastai\tabular\core.py", line 179, in setup
    def setup(self): self.procs.setup(self)
  File "C:\Users\analytiikka\miniconda3\envs\mlModels\lib\site-packages\fastcore\transform.py", line 200, in setup
    for t in tfms: self.add(t,items, train_setup)
  File "C:\Users\analytiikka\miniconda3\envs\mlModels\lib\site-packages\fastcore\transform.py", line 204, in add
    for t in ts: t.setup(items, train_setup)
  File "C:\Users\analytiikka\miniconda3\envs\mlModels\lib\site-packages\fastai\tabular\core.py", line 224, in setup
    super().setup(getattr(items,'train',items), train_setup=False)
  File "C:\Users\analytiikka\miniconda3\envs\mlModels\lib\site-packages\fastcore\transform.py", line 87, in setup
    return self.setups(getattr(items, 'train', items) if train_setup else items)
  File "C:\Users\analytiikka\miniconda3\envs\mlModels\lib\site-packages\fastcore\dispatch.py", line 120, in __call__
    return f(*args, **kwargs)
  File "C:\Users\analytiikka\miniconda3\envs\mlModels\lib\site-packages\fastai\tabular\core.py", line 302, in setups
    missing = pd.isnull(to.conts).any()
  File "C:\Users\analytiikka\miniconda3\envs\mlModels\lib\site-packages\fastai\tabular\core.py", line 208, in f
    def f(o): return o[list(getattr(o,nm+'_names'))]
  File "C:\Users\analytiikka\miniconda3\envs\mlModels\lib\site-packages\fastcore\foundation.py", line 88, in __getitem__
    def __getitem__(self, k): return self.items[list(k) if isinstance(k,CollBase) else k]
  File "C:\Users\analytiikka\miniconda3\envs\mlModels\lib\site-packages\pandas\core\frame.py", line 3511, in __getitem__
    indexer = self.columns._get_indexer_strict(key, "columns")[1]
  File "C:\Users\analytiikka\miniconda3\envs\mlModels\lib\site-packages\pandas\core\indexes\base.py", line 5782, in _get_indexer_strict
    self._raise_if_missing(keyarr, indexer, axis_name)
  File "C:\Users\analytiikka\miniconda3\envs\mlModels\lib\site-packages\pandas\core\indexes\base.py", line 5842, in _raise_if_missing
    raise KeyError(f"None of [{key}] are in the [{axis_name}]")
KeyError: "None of [Index([22.0, 'S', 7.25, 0, 3, 'male', 1, 0], dtype='object')] are in the [columns]"
2023-08-16 10:37:12,089 - INFO - __main__ : 287 - ExecuteFunction (functionId: 3)
2023-08-16 10:37:12,108 - ERROR - _server : 471 - Exception iterating responses: "None of [Index([22.0, 'S', 7.25, 0, 3, 'male', 1, 0], dtype='object')] are in the [columns]"
Traceback (most recent call last):
  File "C:\Users\analytiikka\miniconda3\envs\mlModels\lib\site-packages\grpc\_server.py", line 461, in _take_response_from_response_iterator
    return next(response_iterator), True
  File "__main__.py", line 136, in _random_forest
    to = TabularPandas(
  File "C:\Users\analytiikka\miniconda3\envs\mlModels\lib\site-packages\fastai\tabular\core.py", line 168, in __init__
    if do_setup: self.setup()
  File "C:\Users\analytiikka\miniconda3\envs\mlModels\lib\site-packages\fastai\tabular\core.py", line 179, in setup
    def setup(self): self.procs.setup(self)
  File "C:\Users\analytiikka\miniconda3\envs\mlModels\lib\site-packages\fastcore\transform.py", line 200, in setup
    for t in tfms: self.add(t,items, train_setup)
  File "C:\Users\analytiikka\miniconda3\envs\mlModels\lib\site-packages\fastcore\transform.py", line 204, in add
    for t in ts: t.setup(items, train_setup)
  File "C:\Users\analytiikka\miniconda3\envs\mlModels\lib\site-packages\fastai\tabular\core.py", line 224, in setup
    super().setup(getattr(items,'train',items), train_setup=False)
  File "C:\Users\analytiikka\miniconda3\envs\mlModels\lib\site-packages\fastcore\transform.py", line 87, in setup
    return self.setups(getattr(items, 'train', items) if train_setup else items)
  File "C:\Users\analytiikka\miniconda3\envs\mlModels\lib\site-packages\fastcore\dispatch.py", line 120, in __call__
    return f(*args, **kwargs)
  File "C:\Users\analytiikka\miniconda3\envs\mlModels\lib\site-packages\fastai\tabular\core.py", line 302, in setups
    missing = pd.isnull(to.conts).any()
  File "C:\Users\analytiikka\miniconda3\envs\mlModels\lib\site-packages\fastai\tabular\core.py", line 208, in f
    def f(o): return o[list(getattr(o,nm+'_names'))]
  File "C:\Users\analytiikka\miniconda3\envs\mlModels\lib\site-packages\fastcore\foundation.py", line 88, in __getitem__
    def __getitem__(self, k): return self.items[list(k) if isinstance(k,CollBase) else k]
  File "C:\Users\analytiikka\miniconda3\envs\mlModels\lib\site-packages\pandas\core\frame.py", line 3511, in __getitem__
    indexer = self.columns._get_indexer_strict(key, "columns")[1]
  File "C:\Users\analytiikka\miniconda3\envs\mlModels\lib\site-packages\pandas\core\indexes\base.py", line 5782, in _get_indexer_strict
    self._raise_if_missing(keyarr, indexer, axis_name)
  File "C:\Users\analytiikka\miniconda3\envs\mlModels\lib\site-packages\pandas\core\indexes\base.py", line 5842, in _raise_if_missing
    raise KeyError(f"None of [{key}] are in the [{axis_name}]")
KeyError: "None of [Index([22.0, 'S', 7.25, 0, 3, 'male', 1, 0], dtype='object')] are in the [columns]"
2023-08-16 10:37:15,540 - INFO - __main__ : 287 - ExecuteFunction (functionId: 3)
2023-08-16 10:37:15,559 - ERROR - _server : 471 - Exception iterating responses: "None of [Index([22.0, 'S', 7.25, 0, 3, 'male', 1, 0], dtype='object')] are in the [columns]"
Traceback (most recent call last):
  File "C:\Users\analytiikka\miniconda3\envs\mlModels\lib\site-packages\grpc\_server.py", line 461, in _take_response_from_response_iterator
    return next(response_iterator), True
  File "__main__.py", line 136, in _random_forest
    to = TabularPandas(
  File "C:\Users\analytiikka\miniconda3\envs\mlModels\lib\site-packages\fastai\tabular\core.py", line 168, in __init__
    if do_setup: self.setup()
  File "C:\Users\analytiikka\miniconda3\envs\mlModels\lib\site-packages\fastai\tabular\core.py", line 179, in setup
    def setup(self): self.procs.setup(self)
  File "C:\Users\analytiikka\miniconda3\envs\mlModels\lib\site-packages\fastcore\transform.py", line 200, in setup
    for t in tfms: self.add(t,items, train_setup)
  File "C:\Users\analytiikka\miniconda3\envs\mlModels\lib\site-packages\fastcore\transform.py", line 204, in add
    for t in ts: t.setup(items, train_setup)
  File "C:\Users\analytiikka\miniconda3\envs\mlModels\lib\site-packages\fastai\tabular\core.py", line 224, in setup
    super().setup(getattr(items,'train',items), train_setup=False)
  File "C:\Users\analytiikka\miniconda3\envs\mlModels\lib\site-packages\fastcore\transform.py", line 87, in setup
    return self.setups(getattr(items, 'train', items) if train_setup else items)
  File "C:\Users\analytiikka\miniconda3\envs\mlModels\lib\site-packages\fastcore\dispatch.py", line 120, in __call__
    return f(*args, **kwargs)
  File "C:\Users\analytiikka\miniconda3\envs\mlModels\lib\site-packages\fastai\tabular\core.py", line 302, in setups
    missing = pd.isnull(to.conts).any()
  File "C:\Users\analytiikka\miniconda3\envs\mlModels\lib\site-packages\fastai\tabular\core.py", line 208, in f
    def f(o): return o[list(getattr(o,nm+'_names'))]
  File "C:\Users\analytiikka\miniconda3\envs\mlModels\lib\site-packages\fastcore\foundation.py", line 88, in __getitem__
    def __getitem__(self, k): return self.items[list(k) if isinstance(k,CollBase) else k]
  File "C:\Users\analytiikka\miniconda3\envs\mlModels\lib\site-packages\pandas\core\frame.py", line 3511, in __getitem__
    indexer = self.columns._get_indexer_strict(key, "columns")[1]
  File "C:\Users\analytiikka\miniconda3\envs\mlModels\lib\site-packages\pandas\core\indexes\base.py", line 5782, in _get_indexer_strict
    self._raise_if_missing(keyarr, indexer, axis_name)
  File "C:\Users\analytiikka\miniconda3\envs\mlModels\lib\site-packages\pandas\core\indexes\base.py", line 5842, in _raise_if_missing
    raise KeyError(f"None of [{key}] are in the [{axis_name}]")
KeyError: "None of [Index([22.0, 'S', 7.25, 0, 3, 'male', 1, 0], dtype='object')] are in the [columns]"
2023-08-16 10:37:15,559 - INFO - __main__ : 287 - ExecuteFunction (functionId: 3)
2023-08-16 10:37:15,578 - ERROR - _server : 471 - Exception iterating responses: "None of [Index([22.0, 'S', 7.25, 0, 3, 'male', 1, 0], dtype='object')] are in the [columns]"
Traceback (most recent call last):
  File "C:\Users\analytiikka\miniconda3\envs\mlModels\lib\site-packages\grpc\_server.py", line 461, in _take_response_from_response_iterator
    return next(response_iterator), True
  File "__main__.py", line 136, in _random_forest
    to = TabularPandas(
  File "C:\Users\analytiikka\miniconda3\envs\mlModels\lib\site-packages\fastai\tabular\core.py", line 168, in __init__
    if do_setup: self.setup()
  File "C:\Users\analytiikka\miniconda3\envs\mlModels\lib\site-packages\fastai\tabular\core.py", line 179, in setup
    def setup(self): self.procs.setup(self)
  File "C:\Users\analytiikka\miniconda3\envs\mlModels\lib\site-packages\fastcore\transform.py", line 200, in setup
    for t in tfms: self.add(t,items, train_setup)
  File "C:\Users\analytiikka\miniconda3\envs\mlModels\lib\site-packages\fastcore\transform.py", line 204, in add
    for t in ts: t.setup(items, train_setup)
  File "C:\Users\analytiikka\miniconda3\envs\mlModels\lib\site-packages\fastai\tabular\core.py", line 224, in setup
    super().setup(getattr(items,'train',items), train_setup=False)
  File "C:\Users\analytiikka\miniconda3\envs\mlModels\lib\site-packages\fastcore\transform.py", line 87, in setup
    return self.setups(getattr(items, 'train', items) if train_setup else items)
  File "C:\Users\analytiikka\miniconda3\envs\mlModels\lib\site-packages\fastcore\dispatch.py", line 120, in __call__
    return f(*args, **kwargs)
  File "C:\Users\analytiikka\miniconda3\envs\mlModels\lib\site-packages\fastai\tabular\core.py", line 302, in setups
    missing = pd.isnull(to.conts).any()
  File "C:\Users\analytiikka\miniconda3\envs\mlModels\lib\site-packages\fastai\tabular\core.py", line 208, in f
    def f(o): return o[list(getattr(o,nm+'_names'))]
  File "C:\Users\analytiikka\miniconda3\envs\mlModels\lib\site-packages\fastcore\foundation.py", line 88, in __getitem__
    def __getitem__(self, k): return self.items[list(k) if isinstance(k,CollBase) else k]
  File "C:\Users\analytiikka\miniconda3\envs\mlModels\lib\site-packages\pandas\core\frame.py", line 3511, in __getitem__
    indexer = self.columns._get_indexer_strict(key, "columns")[1]
  File "C:\Users\analytiikka\miniconda3\envs\mlModels\lib\site-packages\pandas\core\indexes\base.py", line 5782, in _get_indexer_strict
    self._raise_if_missing(keyarr, indexer, axis_name)
  File "C:\Users\analytiikka\miniconda3\envs\mlModels\lib\site-packages\pandas\core\indexes\base.py", line 5842, in _raise_if_missing
    raise KeyError(f"None of [{key}] are in the [{axis_name}]")
KeyError: "None of [Index([22.0, 'S', 7.25, 0, 3, 'male', 1, 0], dtype='object')] are in the [columns]"
2023-08-16 10:58:29,485 - INFO - __main__ : 45 - Logging enabled
2023-08-16 10:59:10,254 - INFO - __main__ : 354 - *** Running server in insecure mode on port: 50052 ***
2023-08-16 10:59:14,135 - INFO - __main__ : 245 - GetCapabilities
2023-08-16 10:59:14,135 - INFO - __main__ : 270 - Adding to capabilities: SumOfRows(['col1', 'col2'])
2023-08-16 10:59:14,135 - INFO - __main__ : 270 - Adding to capabilities: SumOfColumn(['col1'])
2023-08-16 10:59:14,135 - INFO - __main__ : 270 - Adding to capabilities: MaxOfColumns_2(['col1', 'col2'])
2023-08-16 10:59:14,135 - INFO - __main__ : 270 - Adding to capabilities: RandomForest(['col1'])
2023-08-16 10:59:27,968 - INFO - __main__ : 287 - ExecuteFunction (functionId: 3)
2023-08-16 10:59:27,985 - ERROR - _server : 471 - Exception iterating responses: "None of [Index([22.0, 'S', 7.25, 0, 3, 'male', 1, 0], dtype='object')] are in the [columns]"
Traceback (most recent call last):
  File "C:\Users\analytiikka\miniconda3\envs\mlModels\lib\site-packages\grpc\_server.py", line 461, in _take_response_from_response_iterator
    return next(response_iterator), True
  File "__main__.py", line 136, in _random_forest
    to = TabularPandas(
  File "C:\Users\analytiikka\miniconda3\envs\mlModels\lib\site-packages\fastai\tabular\core.py", line 168, in __init__
    if do_setup: self.setup()
  File "C:\Users\analytiikka\miniconda3\envs\mlModels\lib\site-packages\fastai\tabular\core.py", line 179, in setup
    def setup(self): self.procs.setup(self)
  File "C:\Users\analytiikka\miniconda3\envs\mlModels\lib\site-packages\fastcore\transform.py", line 200, in setup
    for t in tfms: self.add(t,items, train_setup)
  File "C:\Users\analytiikka\miniconda3\envs\mlModels\lib\site-packages\fastcore\transform.py", line 204, in add
    for t in ts: t.setup(items, train_setup)
  File "C:\Users\analytiikka\miniconda3\envs\mlModels\lib\site-packages\fastai\tabular\core.py", line 224, in setup
    super().setup(getattr(items,'train',items), train_setup=False)
  File "C:\Users\analytiikka\miniconda3\envs\mlModels\lib\site-packages\fastcore\transform.py", line 87, in setup
    return self.setups(getattr(items, 'train', items) if train_setup else items)
  File "C:\Users\analytiikka\miniconda3\envs\mlModels\lib\site-packages\fastcore\dispatch.py", line 120, in __call__
    return f(*args, **kwargs)
  File "C:\Users\analytiikka\miniconda3\envs\mlModels\lib\site-packages\fastai\tabular\core.py", line 302, in setups
    missing = pd.isnull(to.conts).any()
  File "C:\Users\analytiikka\miniconda3\envs\mlModels\lib\site-packages\fastai\tabular\core.py", line 208, in f
    def f(o): return o[list(getattr(o,nm+'_names'))]
  File "C:\Users\analytiikka\miniconda3\envs\mlModels\lib\site-packages\fastcore\foundation.py", line 88, in __getitem__
    def __getitem__(self, k): return self.items[list(k) if isinstance(k,CollBase) else k]
  File "C:\Users\analytiikka\miniconda3\envs\mlModels\lib\site-packages\pandas\core\frame.py", line 3511, in __getitem__
    indexer = self.columns._get_indexer_strict(key, "columns")[1]
  File "C:\Users\analytiikka\miniconda3\envs\mlModels\lib\site-packages\pandas\core\indexes\base.py", line 5782, in _get_indexer_strict
    self._raise_if_missing(keyarr, indexer, axis_name)
  File "C:\Users\analytiikka\miniconda3\envs\mlModels\lib\site-packages\pandas\core\indexes\base.py", line 5842, in _raise_if_missing
    raise KeyError(f"None of [{key}] are in the [{axis_name}]")
KeyError: "None of [Index([22.0, 'S', 7.25, 0, 3, 'male', 1, 0], dtype='object')] are in the [columns]"
2023-08-16 10:59:27,995 - INFO - __main__ : 287 - ExecuteFunction (functionId: 3)
2023-08-16 10:59:28,014 - ERROR - _server : 471 - Exception iterating responses: "None of [Index([22.0, 'S', 7.25, 0, 3, 'male', 1, 0], dtype='object')] are in the [columns]"
Traceback (most recent call last):
  File "C:\Users\analytiikka\miniconda3\envs\mlModels\lib\site-packages\grpc\_server.py", line 461, in _take_response_from_response_iterator
    return next(response_iterator), True
  File "__main__.py", line 136, in _random_forest
    to = TabularPandas(
  File "C:\Users\analytiikka\miniconda3\envs\mlModels\lib\site-packages\fastai\tabular\core.py", line 168, in __init__
    if do_setup: self.setup()
  File "C:\Users\analytiikka\miniconda3\envs\mlModels\lib\site-packages\fastai\tabular\core.py", line 179, in setup
    def setup(self): self.procs.setup(self)
  File "C:\Users\analytiikka\miniconda3\envs\mlModels\lib\site-packages\fastcore\transform.py", line 200, in setup
    for t in tfms: self.add(t,items, train_setup)
  File "C:\Users\analytiikka\miniconda3\envs\mlModels\lib\site-packages\fastcore\transform.py", line 204, in add
    for t in ts: t.setup(items, train_setup)
  File "C:\Users\analytiikka\miniconda3\envs\mlModels\lib\site-packages\fastai\tabular\core.py", line 224, in setup
    super().setup(getattr(items,'train',items), train_setup=False)
  File "C:\Users\analytiikka\miniconda3\envs\mlModels\lib\site-packages\fastcore\transform.py", line 87, in setup
    return self.setups(getattr(items, 'train', items) if train_setup else items)
  File "C:\Users\analytiikka\miniconda3\envs\mlModels\lib\site-packages\fastcore\dispatch.py", line 120, in __call__
    return f(*args, **kwargs)
  File "C:\Users\analytiikka\miniconda3\envs\mlModels\lib\site-packages\fastai\tabular\core.py", line 302, in setups
    missing = pd.isnull(to.conts).any()
  File "C:\Users\analytiikka\miniconda3\envs\mlModels\lib\site-packages\fastai\tabular\core.py", line 208, in f
    def f(o): return o[list(getattr(o,nm+'_names'))]
  File "C:\Users\analytiikka\miniconda3\envs\mlModels\lib\site-packages\fastcore\foundation.py", line 88, in __getitem__
    def __getitem__(self, k): return self.items[list(k) if isinstance(k,CollBase) else k]
  File "C:\Users\analytiikka\miniconda3\envs\mlModels\lib\site-packages\pandas\core\frame.py", line 3511, in __getitem__
    indexer = self.columns._get_indexer_strict(key, "columns")[1]
  File "C:\Users\analytiikka\miniconda3\envs\mlModels\lib\site-packages\pandas\core\indexes\base.py", line 5782, in _get_indexer_strict
    self._raise_if_missing(keyarr, indexer, axis_name)
  File "C:\Users\analytiikka\miniconda3\envs\mlModels\lib\site-packages\pandas\core\indexes\base.py", line 5842, in _raise_if_missing
    raise KeyError(f"None of [{key}] are in the [{axis_name}]")
KeyError: "None of [Index([22.0, 'S', 7.25, 0, 3, 'male', 1, 0], dtype='object')] are in the [columns]"
2023-08-16 10:59:28,016 - INFO - __main__ : 287 - ExecuteFunction (functionId: 3)
2023-08-16 10:59:28,034 - ERROR - _server : 471 - Exception iterating responses: "None of [Index([22.0, 'S', 7.25, 0, 3, 'male', 1, 0], dtype='object')] are in the [columns]"
Traceback (most recent call last):
  File "C:\Users\analytiikka\miniconda3\envs\mlModels\lib\site-packages\grpc\_server.py", line 461, in _take_response_from_response_iterator
    return next(response_iterator), True
  File "__main__.py", line 136, in _random_forest
    to = TabularPandas(
  File "C:\Users\analytiikka\miniconda3\envs\mlModels\lib\site-packages\fastai\tabular\core.py", line 168, in __init__
    if do_setup: self.setup()
  File "C:\Users\analytiikka\miniconda3\envs\mlModels\lib\site-packages\fastai\tabular\core.py", line 179, in setup
    def setup(self): self.procs.setup(self)
  File "C:\Users\analytiikka\miniconda3\envs\mlModels\lib\site-packages\fastcore\transform.py", line 200, in setup
    for t in tfms: self.add(t,items, train_setup)
  File "C:\Users\analytiikka\miniconda3\envs\mlModels\lib\site-packages\fastcore\transform.py", line 204, in add
    for t in ts: t.setup(items, train_setup)
  File "C:\Users\analytiikka\miniconda3\envs\mlModels\lib\site-packages\fastai\tabular\core.py", line 224, in setup
    super().setup(getattr(items,'train',items), train_setup=False)
  File "C:\Users\analytiikka\miniconda3\envs\mlModels\lib\site-packages\fastcore\transform.py", line 87, in setup
    return self.setups(getattr(items, 'train', items) if train_setup else items)
  File "C:\Users\analytiikka\miniconda3\envs\mlModels\lib\site-packages\fastcore\dispatch.py", line 120, in __call__
    return f(*args, **kwargs)
  File "C:\Users\analytiikka\miniconda3\envs\mlModels\lib\site-packages\fastai\tabular\core.py", line 302, in setups
    missing = pd.isnull(to.conts).any()
  File "C:\Users\analytiikka\miniconda3\envs\mlModels\lib\site-packages\fastai\tabular\core.py", line 208, in f
    def f(o): return o[list(getattr(o,nm+'_names'))]
  File "C:\Users\analytiikka\miniconda3\envs\mlModels\lib\site-packages\fastcore\foundation.py", line 88, in __getitem__
    def __getitem__(self, k): return self.items[list(k) if isinstance(k,CollBase) else k]
  File "C:\Users\analytiikka\miniconda3\envs\mlModels\lib\site-packages\pandas\core\frame.py", line 3511, in __getitem__
    indexer = self.columns._get_indexer_strict(key, "columns")[1]
  File "C:\Users\analytiikka\miniconda3\envs\mlModels\lib\site-packages\pandas\core\indexes\base.py", line 5782, in _get_indexer_strict
    self._raise_if_missing(keyarr, indexer, axis_name)
  File "C:\Users\analytiikka\miniconda3\envs\mlModels\lib\site-packages\pandas\core\indexes\base.py", line 5842, in _raise_if_missing
    raise KeyError(f"None of [{key}] are in the [{axis_name}]")
KeyError: "None of [Index([22.0, 'S', 7.25, 0, 3, 'male', 1, 0], dtype='object')] are in the [columns]"
2023-08-16 10:59:28,034 - INFO - __main__ : 287 - ExecuteFunction (functionId: 3)
2023-08-16 10:59:28,046 - ERROR - _server : 471 - Exception iterating responses: "None of [Index([22.0, 'S', 7.25, 0, 3, 'male', 1, 0], dtype='object')] are in the [columns]"
Traceback (most recent call last):
  File "C:\Users\analytiikka\miniconda3\envs\mlModels\lib\site-packages\grpc\_server.py", line 461, in _take_response_from_response_iterator
    return next(response_iterator), True
  File "__main__.py", line 136, in _random_forest
    to = TabularPandas(
  File "C:\Users\analytiikka\miniconda3\envs\mlModels\lib\site-packages\fastai\tabular\core.py", line 168, in __init__
    if do_setup: self.setup()
  File "C:\Users\analytiikka\miniconda3\envs\mlModels\lib\site-packages\fastai\tabular\core.py", line 179, in setup
    def setup(self): self.procs.setup(self)
  File "C:\Users\analytiikka\miniconda3\envs\mlModels\lib\site-packages\fastcore\transform.py", line 200, in setup
    for t in tfms: self.add(t,items, train_setup)
  File "C:\Users\analytiikka\miniconda3\envs\mlModels\lib\site-packages\fastcore\transform.py", line 204, in add
    for t in ts: t.setup(items, train_setup)
  File "C:\Users\analytiikka\miniconda3\envs\mlModels\lib\site-packages\fastai\tabular\core.py", line 224, in setup
    super().setup(getattr(items,'train',items), train_setup=False)
  File "C:\Users\analytiikka\miniconda3\envs\mlModels\lib\site-packages\fastcore\transform.py", line 87, in setup
    return self.setups(getattr(items, 'train', items) if train_setup else items)
  File "C:\Users\analytiikka\miniconda3\envs\mlModels\lib\site-packages\fastcore\dispatch.py", line 120, in __call__
    return f(*args, **kwargs)
  File "C:\Users\analytiikka\miniconda3\envs\mlModels\lib\site-packages\fastai\tabular\core.py", line 302, in setups
    missing = pd.isnull(to.conts).any()
  File "C:\Users\analytiikka\miniconda3\envs\mlModels\lib\site-packages\fastai\tabular\core.py", line 208, in f
    def f(o): return o[list(getattr(o,nm+'_names'))]
  File "C:\Users\analytiikka\miniconda3\envs\mlModels\lib\site-packages\fastcore\foundation.py", line 88, in __getitem__
    def __getitem__(self, k): return self.items[list(k) if isinstance(k,CollBase) else k]
  File "C:\Users\analytiikka\miniconda3\envs\mlModels\lib\site-packages\pandas\core\frame.py", line 3511, in __getitem__
    indexer = self.columns._get_indexer_strict(key, "columns")[1]
  File "C:\Users\analytiikka\miniconda3\envs\mlModels\lib\site-packages\pandas\core\indexes\base.py", line 5782, in _get_indexer_strict
    self._raise_if_missing(keyarr, indexer, axis_name)
  File "C:\Users\analytiikka\miniconda3\envs\mlModels\lib\site-packages\pandas\core\indexes\base.py", line 5842, in _raise_if_missing
    raise KeyError(f"None of [{key}] are in the [{axis_name}]")
KeyError: "None of [Index([22.0, 'S', 7.25, 0, 3, 'male', 1, 0], dtype='object')] are in the [columns]"
2023-08-16 10:59:30,856 - INFO - __main__ : 287 - ExecuteFunction (functionId: 3)
2023-08-16 10:59:30,873 - ERROR - _server : 471 - Exception iterating responses: "None of [Index([22.0, 'S', 7.25, 0, 3, 'male', 1, 0], dtype='object')] are in the [columns]"
Traceback (most recent call last):
  File "C:\Users\analytiikka\miniconda3\envs\mlModels\lib\site-packages\grpc\_server.py", line 461, in _take_response_from_response_iterator
    return next(response_iterator), True
  File "__main__.py", line 136, in _random_forest
    to = TabularPandas(
  File "C:\Users\analytiikka\miniconda3\envs\mlModels\lib\site-packages\fastai\tabular\core.py", line 168, in __init__
    if do_setup: self.setup()
  File "C:\Users\analytiikka\miniconda3\envs\mlModels\lib\site-packages\fastai\tabular\core.py", line 179, in setup
    def setup(self): self.procs.setup(self)
  File "C:\Users\analytiikka\miniconda3\envs\mlModels\lib\site-packages\fastcore\transform.py", line 200, in setup
    for t in tfms: self.add(t,items, train_setup)
  File "C:\Users\analytiikka\miniconda3\envs\mlModels\lib\site-packages\fastcore\transform.py", line 204, in add
    for t in ts: t.setup(items, train_setup)
  File "C:\Users\analytiikka\miniconda3\envs\mlModels\lib\site-packages\fastai\tabular\core.py", line 224, in setup
    super().setup(getattr(items,'train',items), train_setup=False)
  File "C:\Users\analytiikka\miniconda3\envs\mlModels\lib\site-packages\fastcore\transform.py", line 87, in setup
    return self.setups(getattr(items, 'train', items) if train_setup else items)
  File "C:\Users\analytiikka\miniconda3\envs\mlModels\lib\site-packages\fastcore\dispatch.py", line 120, in __call__
    return f(*args, **kwargs)
  File "C:\Users\analytiikka\miniconda3\envs\mlModels\lib\site-packages\fastai\tabular\core.py", line 302, in setups
    missing = pd.isnull(to.conts).any()
  File "C:\Users\analytiikka\miniconda3\envs\mlModels\lib\site-packages\fastai\tabular\core.py", line 208, in f
    def f(o): return o[list(getattr(o,nm+'_names'))]
  File "C:\Users\analytiikka\miniconda3\envs\mlModels\lib\site-packages\fastcore\foundation.py", line 88, in __getitem__
    def __getitem__(self, k): return self.items[list(k) if isinstance(k,CollBase) else k]
  File "C:\Users\analytiikka\miniconda3\envs\mlModels\lib\site-packages\pandas\core\frame.py", line 3511, in __getitem__
    indexer = self.columns._get_indexer_strict(key, "columns")[1]
  File "C:\Users\analytiikka\miniconda3\envs\mlModels\lib\site-packages\pandas\core\indexes\base.py", line 5782, in _get_indexer_strict
    self._raise_if_missing(keyarr, indexer, axis_name)
  File "C:\Users\analytiikka\miniconda3\envs\mlModels\lib\site-packages\pandas\core\indexes\base.py", line 5842, in _raise_if_missing
    raise KeyError(f"None of [{key}] are in the [{axis_name}]")
KeyError: "None of [Index([22.0, 'S', 7.25, 0, 3, 'male', 1, 0], dtype='object')] are in the [columns]"
2023-08-16 10:59:30,875 - INFO - __main__ : 287 - ExecuteFunction (functionId: 3)
2023-08-16 10:59:30,894 - ERROR - _server : 471 - Exception iterating responses: "None of [Index([22.0, 'S', 7.25, 0, 3, 'male', 1, 0], dtype='object')] are in the [columns]"
Traceback (most recent call last):
  File "C:\Users\analytiikka\miniconda3\envs\mlModels\lib\site-packages\grpc\_server.py", line 461, in _take_response_from_response_iterator
    return next(response_iterator), True
  File "__main__.py", line 136, in _random_forest
    to = TabularPandas(
  File "C:\Users\analytiikka\miniconda3\envs\mlModels\lib\site-packages\fastai\tabular\core.py", line 168, in __init__
    if do_setup: self.setup()
  File "C:\Users\analytiikka\miniconda3\envs\mlModels\lib\site-packages\fastai\tabular\core.py", line 179, in setup
    def setup(self): self.procs.setup(self)
  File "C:\Users\analytiikka\miniconda3\envs\mlModels\lib\site-packages\fastcore\transform.py", line 200, in setup
    for t in tfms: self.add(t,items, train_setup)
  File "C:\Users\analytiikka\miniconda3\envs\mlModels\lib\site-packages\fastcore\transform.py", line 204, in add
    for t in ts: t.setup(items, train_setup)
  File "C:\Users\analytiikka\miniconda3\envs\mlModels\lib\site-packages\fastai\tabular\core.py", line 224, in setup
    super().setup(getattr(items,'train',items), train_setup=False)
  File "C:\Users\analytiikka\miniconda3\envs\mlModels\lib\site-packages\fastcore\transform.py", line 87, in setup
    return self.setups(getattr(items, 'train', items) if train_setup else items)
  File "C:\Users\analytiikka\miniconda3\envs\mlModels\lib\site-packages\fastcore\dispatch.py", line 120, in __call__
    return f(*args, **kwargs)
  File "C:\Users\analytiikka\miniconda3\envs\mlModels\lib\site-packages\fastai\tabular\core.py", line 302, in setups
    missing = pd.isnull(to.conts).any()
  File "C:\Users\analytiikka\miniconda3\envs\mlModels\lib\site-packages\fastai\tabular\core.py", line 208, in f
    def f(o): return o[list(getattr(o,nm+'_names'))]
  File "C:\Users\analytiikka\miniconda3\envs\mlModels\lib\site-packages\fastcore\foundation.py", line 88, in __getitem__
    def __getitem__(self, k): return self.items[list(k) if isinstance(k,CollBase) else k]
  File "C:\Users\analytiikka\miniconda3\envs\mlModels\lib\site-packages\pandas\core\frame.py", line 3511, in __getitem__
    indexer = self.columns._get_indexer_strict(key, "columns")[1]
  File "C:\Users\analytiikka\miniconda3\envs\mlModels\lib\site-packages\pandas\core\indexes\base.py", line 5782, in _get_indexer_strict
    self._raise_if_missing(keyarr, indexer, axis_name)
  File "C:\Users\analytiikka\miniconda3\envs\mlModels\lib\site-packages\pandas\core\indexes\base.py", line 5842, in _raise_if_missing
    raise KeyError(f"None of [{key}] are in the [{axis_name}]")
KeyError: "None of [Index([22.0, 'S', 7.25, 0, 3, 'male', 1, 0], dtype='object')] are in the [columns]"
2023-08-16 11:01:24,835 - INFO - __main__ : 45 - Logging enabled
2023-08-16 11:01:24,964 - INFO - __main__ : 358 - *** Running server in insecure mode on port: 50052 ***
2023-08-16 11:01:27,085 - INFO - __main__ : 249 - GetCapabilities
2023-08-16 11:01:27,085 - INFO - __main__ : 274 - Adding to capabilities: SumOfRows(['col1', 'col2'])
2023-08-16 11:01:27,085 - INFO - __main__ : 274 - Adding to capabilities: SumOfColumn(['col1'])
2023-08-16 11:01:27,085 - INFO - __main__ : 274 - Adding to capabilities: MaxOfColumns_2(['col1', 'col2'])
2023-08-16 11:01:27,085 - INFO - __main__ : 274 - Adding to capabilities: RandomForest(['col1'])
2023-08-16 11:01:28,541 - INFO - __main__ : 291 - ExecuteFunction (functionId: 3)
2023-08-16 11:03:07,259 - INFO - __main__ : 45 - Logging enabled
2023-08-16 11:03:07,259 - INFO - __main__ : 358 - *** Running server in insecure mode on port: 50052 ***
2023-08-16 11:03:07,477 - INFO - __main__ : 249 - GetCapabilities
2023-08-16 11:03:07,477 - INFO - __main__ : 274 - Adding to capabilities: SumOfRows(['col1', 'col2'])
2023-08-16 11:03:07,477 - INFO - __main__ : 274 - Adding to capabilities: SumOfColumn(['col1'])
2023-08-16 11:03:07,477 - INFO - __main__ : 274 - Adding to capabilities: MaxOfColumns_2(['col1', 'col2'])
2023-08-16 11:03:07,477 - INFO - __main__ : 274 - Adding to capabilities: RandomForest(['col1'])
2023-08-16 11:03:12,728 - INFO - __main__ : 291 - ExecuteFunction (functionId: 3)
2023-08-16 11:05:02,330 - INFO - __main__ : 45 - Logging enabled
2023-08-16 11:05:02,330 - INFO - __main__ : 358 - *** Running server in insecure mode on port: 50052 ***
2023-08-16 11:05:02,580 - INFO - __main__ : 249 - GetCapabilities
2023-08-16 11:05:02,580 - INFO - __main__ : 274 - Adding to capabilities: SumOfRows(['col1', 'col2'])
2023-08-16 11:05:02,580 - INFO - __main__ : 274 - Adding to capabilities: SumOfColumn(['col1'])
2023-08-16 11:05:02,580 - INFO - __main__ : 274 - Adding to capabilities: MaxOfColumns_2(['col1', 'col2'])
2023-08-16 11:05:02,580 - INFO - __main__ : 274 - Adding to capabilities: RandomForest(['col1'])
2023-08-16 11:05:05,695 - INFO - __main__ : 291 - ExecuteFunction (functionId: 3)
2023-08-16 11:08:52,868 - INFO - __main__ : 45 - Logging enabled
2023-08-16 11:08:52,872 - INFO - __main__ : 360 - *** Running server in insecure mode on port: 50052 ***
2023-08-16 11:08:53,184 - INFO - __main__ : 251 - GetCapabilities
2023-08-16 11:08:53,184 - INFO - __main__ : 276 - Adding to capabilities: SumOfRows(['col1', 'col2'])
2023-08-16 11:08:53,184 - INFO - __main__ : 276 - Adding to capabilities: SumOfColumn(['col1'])
2023-08-16 11:08:53,184 - INFO - __main__ : 276 - Adding to capabilities: MaxOfColumns_2(['col1', 'col2'])
2023-08-16 11:08:53,184 - INFO - __main__ : 276 - Adding to capabilities: RandomForest(['col1'])
2023-08-16 11:08:56,202 - INFO - __main__ : 293 - ExecuteFunction (functionId: 3)
2023-08-16 11:10:23,305 - INFO - __main__ : 45 - Logging enabled
2023-08-16 11:10:23,305 - INFO - __main__ : 360 - *** Running server in insecure mode on port: 50052 ***
2023-08-16 11:10:23,696 - INFO - __main__ : 251 - GetCapabilities
2023-08-16 11:10:23,696 - INFO - __main__ : 276 - Adding to capabilities: SumOfRows(['col1', 'col2'])
2023-08-16 11:10:23,696 - INFO - __main__ : 276 - Adding to capabilities: SumOfColumn(['col1'])
2023-08-16 11:10:23,696 - INFO - __main__ : 276 - Adding to capabilities: MaxOfColumns_2(['col1', 'col2'])
2023-08-16 11:10:23,696 - INFO - __main__ : 276 - Adding to capabilities: RandomForest(['col1'])
2023-08-16 11:10:27,829 - INFO - __main__ : 293 - ExecuteFunction (functionId: 3)
2023-08-16 11:10:57,003 - INFO - __main__ : 45 - Logging enabled
2023-08-16 11:10:57,003 - INFO - __main__ : 360 - *** Running server in insecure mode on port: 50052 ***
2023-08-16 11:10:57,253 - INFO - __main__ : 251 - GetCapabilities
2023-08-16 11:10:57,253 - INFO - __main__ : 276 - Adding to capabilities: SumOfRows(['col1', 'col2'])
2023-08-16 11:10:57,253 - INFO - __main__ : 276 - Adding to capabilities: SumOfColumn(['col1'])
2023-08-16 11:10:57,253 - INFO - __main__ : 276 - Adding to capabilities: MaxOfColumns_2(['col1', 'col2'])
2023-08-16 11:10:57,253 - INFO - __main__ : 276 - Adding to capabilities: RandomForest(['col1'])
2023-08-16 11:11:01,013 - INFO - __main__ : 293 - ExecuteFunction (functionId: 3)
2023-08-16 11:11:28,210 - INFO - __main__ : 293 - ExecuteFunction (functionId: 3)
2023-08-16 11:15:24,197 - INFO - __main__ : 293 - ExecuteFunction (functionId: 3)
2023-08-16 11:15:29,798 - INFO - __main__ : 293 - ExecuteFunction (functionId: 3)
2023-08-16 11:15:36,259 - INFO - __main__ : 293 - ExecuteFunction (functionId: 3)
2023-08-16 11:15:39,308 - INFO - __main__ : 293 - ExecuteFunction (functionId: 3)
2023-08-16 11:15:44,139 - INFO - __main__ : 293 - ExecuteFunction (functionId: 3)
2023-08-16 11:15:45,971 - INFO - __main__ : 293 - ExecuteFunction (functionId: 3)
2023-08-16 11:15:54,750 - INFO - __main__ : 293 - ExecuteFunction (functionId: 3)
2023-08-16 11:16:52,982 - INFO - __main__ : 293 - ExecuteFunction (functionId: 3)
2023-08-16 11:19:30,227 - INFO - __main__ : 293 - ExecuteFunction (functionId: 3)
2023-08-16 11:48:18,671 - INFO - __main__ : 45 - Logging enabled
2023-08-16 11:48:18,671 - INFO - __main__ : 368 - *** Running server in insecure mode on port: 50052 ***
2023-08-16 11:48:18,721 - INFO - __main__ : 259 - GetCapabilities
2023-08-16 11:48:18,721 - INFO - __main__ : 284 - Adding to capabilities: SumOfRows(['col1', 'col2'])
2023-08-16 11:48:18,721 - INFO - __main__ : 284 - Adding to capabilities: SumOfColumn(['col1'])
2023-08-16 11:48:18,721 - INFO - __main__ : 284 - Adding to capabilities: MaxOfColumns_2(['col1', 'col2'])
2023-08-16 11:48:18,721 - INFO - __main__ : 284 - Adding to capabilities: RandomForest(['col1'])
2023-08-16 11:48:22,227 - INFO - __main__ : 301 - ExecuteFunction (functionId: 3)
2023-08-16 11:48:48,477 - INFO - __main__ : 301 - ExecuteFunction (functionId: 1)
2023-08-16 11:51:48,085 - INFO - __main__ : 45 - Logging enabled
2023-08-16 11:51:48,102 - INFO - __main__ : 370 - *** Running server in insecure mode on port: 50052 ***
2023-08-16 11:51:48,253 - INFO - __main__ : 261 - GetCapabilities
2023-08-16 11:51:48,253 - INFO - __main__ : 286 - Adding to capabilities: SumOfRows(['col1', 'col2'])
2023-08-16 11:51:48,253 - INFO - __main__ : 286 - Adding to capabilities: SumOfColumn(['col1'])
2023-08-16 11:51:48,253 - INFO - __main__ : 286 - Adding to capabilities: MaxOfColumns_2(['col1', 'col2'])
2023-08-16 11:51:48,253 - INFO - __main__ : 286 - Adding to capabilities: RandomForest(['col1'])
2023-08-16 11:51:50,002 - INFO - __main__ : 303 - ExecuteFunction (functionId: 3)
2023-08-16 11:53:07,274 - INFO - __main__ : 45 - Logging enabled
2023-08-16 11:53:07,274 - INFO - __main__ : 370 - *** Running server in insecure mode on port: 50052 ***
2023-08-16 11:53:07,642 - INFO - __main__ : 261 - GetCapabilities
2023-08-16 11:53:07,642 - INFO - __main__ : 286 - Adding to capabilities: SumOfRows(['col1', 'col2'])
2023-08-16 11:53:07,642 - INFO - __main__ : 286 - Adding to capabilities: SumOfColumn(['col1'])
2023-08-16 11:53:07,642 - INFO - __main__ : 286 - Adding to capabilities: MaxOfColumns_2(['col1', 'col2'])
2023-08-16 11:53:07,642 - INFO - __main__ : 286 - Adding to capabilities: RandomForest(['col1'])
2023-08-16 11:53:17,697 - INFO - __main__ : 303 - ExecuteFunction (functionId: 3)
2023-08-16 11:53:49,602 - INFO - __main__ : 303 - ExecuteFunction (functionId: 3)
